Workbook

Sheet Salidas 
A1: Fecha | B1: Codigo de Barras | C1: Unidades | D1: Descripcion del Producto | E1: Metros | F1: Kilos | G1: Descripcion
A2: =NOW() -> 43615.641 | B2: 200611001 | D2: =VLOOKUP(B2,'[1]Base de datos'!$B:$F,2,FALSE) -> Pelicula PVC 35 mic. CH 611 mm | E2: =VLOOKUP(B2,'[1]Base de datos'!$B:$E,3,FALSE) -> 2820 | F2: =VLOOKUP(B2,'[1]Base de datos'!$B:$E,4,FALSE) -> 78
B3: 200611002 | D3: =VLOOKUP(B3,'[1]Base de datos'!$B:$F,2,FALSE) -> Pelicula PVC 35 mic. CH 611 mm | E3: =VLOOKUP(B3,'[1]Base de datos'!$B:$E,3,FALSE) -> 2870 | F3: =VLOOKUP(B3,'[1]Base de datos'!$B:$E,4,FALSE) -> 78.7
B4: 200611003 | D4: =VLOOKUP(B4,'[1]Base de datos'!$B:$F,2,FALSE) -> Pelicula PVC 35 mic. CH 611 mm | E4: =VLOOKUP(B4,'[1]Base de datos'!$B:$E,3,FALSE) -> 2782 | F4: =VLOOKUP(B4,'[1]Base de datos'!$B:$E,4,FALSE) -> 78.8
B5: 200611004 | D5: =VLOOKUP(B5,'[1]Base de datos'!$B:$F,2,FALSE) -> Pelicula PVC 35 mic. CH 611 mm | E5: =VLOOKUP(B5,'[1]Base de datos'!$B:$E,3,FALSE) -> 2941 | F5: =VLOOKUP(B5,'[1]Base de datos'!$B:$E,4,FALSE) -> 81.4
B6: 200611007 | D6: =VLOOKUP(B6,'[1]Base de datos'!$B:$F,2,FALSE) -> Pelicula PVC 35 mic. CH 611 mm | E6: =VLOOKUP(B6,'[1]Base de datos'!$B:$E,3,FALSE) -> 2814 | F6: =VLOOKUP(B6,'[1]Base de datos'!$B:$E,4,FALSE) -> 78.5
B7: 200611009 | D7: =VLOOKUP(B7,'[1]Base de datos'!$B:$F,2,FALSE) -> Pelicula PVC 35 mic. CH 611 mm | E7: =VLOOKUP(B7,'[1]Base de datos'!$B:$E,3,FALSE) -> 2832 | F7: =VLOOKUP(B7,'[1]Base de datos'!$B:$E,4,FALSE) -> 79.7
B8: 200611010 | D8: =VLOOKUP(B8,'[1]Base de datos'!$B:$F,2,FALSE) -> Pelicula PVC 35 mic. CH 611 mm | E8: =VLOOKUP(B8,'[1]Base de datos'!$B:$E,3,FALSE) -> 2916 | F8: =VLOOKUP(B8,'[1]Base de datos'!$B:$E,4,FALSE) -> 82.7
B9: 200611012 | D9: =VLOOKUP(B9,'[1]Base de datos'!$B:$F,2,FALSE) -> Pelicula PVC 35 mic. CH 611 mm | E9: =VLOOKUP(B9,'[1]Base de datos'!$B:$E,3,FALSE) -> 2827 | F9: =VLOOKUP(B9,'[1]Base de datos'!$B:$E,4,FALSE) -> 76.5
B10: 200611031 | D10: =VLOOKUP(B10,'[1]Base de datos'!$B:$F,2,FALSE) -> Pelicula PVC 35 mic. CH 611 mm | E10: =VLOOKUP(B10,'[1]Base de datos'!$B:$E,3,FALSE) -> 2840 | F10: =VLOOKUP(B10,'[1]Base de datos'!$B:$E,4,FALSE) -> 77.6
B11: 200611032 | D11: =VLOOKUP(B11,'[1]Base de datos'!$B:$F,2,FALSE) -> Pelicula PVC 35 mic. CH 611 mm | E11: =VLOOKUP(B11,'[1]Base de datos'!$B:$E,3,FALSE) -> 2926 | F11: =VLOOKUP(B11,'[1]Base de datos'!$B:$E,4,FALSE) -> 82.9
B12: 200611033 | D12: =VLOOKUP(B12,'[1]Base de datos'!$B:$F,2,FALSE) -> Pelicula PVC 35 mic. CH 611 mm | E12: =VLOOKUP(B12,'[1]Base de datos'!$B:$E,3,FALSE) -> 2916 | F12: =VLOOKUP(B12,'[1]Base de datos'!$B:$E,4,FALSE) -> 82
B13: 200611034 | D13: =VLOOKUP(B13,'[1]Base de datos'!$B:$F,2,FALSE) -> Pelicula PVC 35 mic. CH 611 mm | E13: =VLOOKUP(B13,'[1]Base de datos'!$B:$E,3,FALSE) -> 2926 | F13: =VLOOKUP(B13,'[1]Base de datos'!$B:$E,4,FALSE) -> 82.5
B14: 200611035 | D14: =VLOOKUP(B14,'[1]Base de datos'!$B:$F,2,FALSE) -> Pelicula PVC 35 mic. CH 611 mm | E14: =VLOOKUP(B14,'[1]Base de datos'!$B:$E,3,FALSE) -> 2807 | F14: =VLOOKUP(B14,'[1]Base de datos'!$B:$E,4,FALSE) -> 80.2
... B118: 200611122 | D118: =VLOOKUP(B118,'[1]Base de datos'!$B:$F,2,FALSE) -> Pelicula PVC 35 mic. CH 611 mm | E118: =VLOOKUP(B118,'[1]Base de datos'!$B:$E,3,FALSE) -> 2834 | F118: =VLOOKUP(B118,'[1]Base de datos'!$B:$E,4,FALSE) -> 81
D119: =VLOOKUP(B119,'[1]Base de datos'!$B:$F,2,FALSE) -> #N/A | E119: =VLOOKUP(B119,'[1]Base de datos'!$B:$E,3,FALSE) -> #N/A | F119: =VLOOKUP(B119,'[1]Base de datos'!$B:$E,4,FALSE) -> #N/A
D120: =VLOOKUP(B120,'[1]Base de datos'!$B:$F,2,FALSE) -> #N/A | E120: =VLOOKUP(B120,'[1]Base de datos'!$B:$E,3,FALSE) -> #N/A | F120: =VLOOKUP(B120,'[1]Base de datos'!$B:$E,4,FALSE) -> #N/A
D121: =VLOOKUP(B121,'[1]Base de datos'!$B:$F,2,FALSE) -> #N/A | E121: =VLOOKUP(B121,'[1]Base de datos'!$B:$E,3,FALSE) -> #N/A | F121: =VLOOKUP(B121,'[1]Base de datos'!$B:$E,4,FALSE) -> #N/A
D122: =VLOOKUP(B122,'[1]Base de datos'!$B:$F,2,FALSE) -> #N/A | E122: =VLOOKUP(B122,'[1]Base de datos'!$B:$E,3,FALSE) -> #N/A | F122: =VLOOKUP(B122,'[1]Base de datos'!$B:$E,4,FALSE) -> #N/A
D123: =VLOOKUP(B123,'[1]Base de datos'!$B:$F,2,FALSE) -> #N/A | E123: =VLOOKUP(B123,'[1]Base de datos'!$B:$E,3,FALSE) -> #N/A | F123: =VLOOKUP(B123,'[1]Base de datos'!$B:$E,4,FALSE) -> #N/A
D124: =VLOOKUP(B124,'[1]Base de datos'!$B:$F,2,FALSE) -> #N/A | E124: =VLOOKUP(B124,'[1]Base de datos'!$B:$E,3,FALSE) -> #N/A | F124: =VLOOKUP(B124,'[1]Base de datos'!$B:$E,4,FALSE) -> #N/A
D125: =VLOOKUP(B125,'[1]Base de datos'!$B:$F,2,FALSE) -> #N/A | E125: =VLOOKUP(B125,'[1]Base de datos'!$B:$E,3,FALSE) -> #N/A | F125: =VLOOKUP(B125,'[1]Base de datos'!$B:$E,4,FALSE) -> #N/A
D126: =VLOOKUP(B126,'[1]Base de datos'!$B:$F,2,FALSE) -> #N/A | E126: =VLOOKUP(B126,'[1]Base de datos'!$B:$E,3,FALSE) -> #N/A | F126: =VLOOKUP(B126,'[1]Base de datos'!$B:$E,4,FALSE) -> #N/A
D127: =VLOOKUP(B127,'[1]Base de datos'!$B:$F,2,FALSE) -> #N/A | E127: =VLOOKUP(B127,'[1]Base de datos'!$B:$E,3,FALSE) -> #N/A | F127: =VLOOKUP(B127,'[1]Base de datos'!$B:$E,4,FALSE) -> #N/A
D128: =VLOOKUP(B128,'[1]Base de datos'!$B:$F,2,FALSE) -> #N/A | E128: =VLOOKUP(B128,'[1]Base de datos'!$B:$E,3,FALSE) -> #N/A | F128: =VLOOKUP(B128,'[1]Base de datos'!$B:$E,4,FALSE) -> #N/A
D129: =VLOOKUP(B129,'[1]Base de datos'!$B:$F,2,FALSE) -> #N/A | E129: =VLOOKUP(B129,'[1]Base de datos'!$B:$E,3,FALSE) -> #N/A | F129: =VLOOKUP(B129,'[1]Base de datos'!$B:$E,4,FALSE) -> #N/A
D130: =VLOOKUP(B130,'[1]Base de datos'!$B:$F,2,FALSE) -> #N/A | E130: =VLOOKUP(B130,'[1]Base de datos'!$B:$E,3,FALSE) -> #N/A | F130: =VLOOKUP(B130,'[1]Base de datos'!$B:$E,4,FALSE) -> #N/A
... D903: =VLOOKUP(B903,'[1]Base de datos'!$B:$F,2,FALSE) -> #N/A | E903: =VLOOKUP(B903,'[1]Base de datos'!$B:$E,3,FALSE) -> #N/A | F903: =VLOOKUP(B903,'[1]Base de datos'!$B:$E,4,FALSE) -> #N/A

Sheet Entradas 
A1: Fecha | B1: Codigo de Barras | C1: Unidades | D1: Descripcion del Producto | E1: Metros | F1: Kilos | G1: Descripcion
A2: =NOW() -> 43615.641 | D2: =VLOOKUP(B2,'[1]Base de datos'!$B:$F,2,FALSE) -> #N/A | E2: =VLOOKUP(B2,'[1]Base de datos'!$B:$E,3,FALSE) -> #N/A | F2: =VLOOKUP(B2,'[1]Base de datos'!$B:$E,4,FALSE) -> #N/A
B3: 200611001 | D3: =VLOOKUP(B3,'[1]Base de datos'!$B:$F,2,FALSE) -> Pelicula PVC 35 mic. CH 611 mm | E3: =VLOOKUP(B3,'[1]Base de datos'!$B:$E,3,FALSE) -> 2820 | F3: =VLOOKUP(B3,'[1]Base de datos'!$B:$E,4,FALSE) -> 78
B4: =+B3+1 -> 200611002 | D4: =VLOOKUP(B4,'[1]Base de datos'!$B:$F,2,FALSE) -> Pelicula PVC 35 mic. CH 611 mm | E4: =VLOOKUP(B4,'[1]Base de datos'!$B:$E,3,FALSE) -> 2870 | F4: =VLOOKUP(B4,'[1]Base de datos'!$B:$E,4,FALSE) -> 78.7
B5: =+B4+1 -> 200611003 | D5: =VLOOKUP(B5,'[1]Base de datos'!$B:$F,2,FALSE) -> Pelicula PVC 35 mic. CH 611 mm | E5: =VLOOKUP(B5,'[1]Base de datos'!$B:$E,3,FALSE) -> 2782 | F5: =VLOOKUP(B5,'[1]Base de datos'!$B:$E,4,FALSE) -> 78.8
B6: =+B5+1 -> 200611004 | D6: =VLOOKUP(B6,'[1]Base de datos'!$B:$F,2,FALSE) -> Pelicula PVC 35 mic. CH 611 mm | E6: =VLOOKUP(B6,'[1]Base de datos'!$B:$E,3,FALSE) -> 2941 | F6: =VLOOKUP(B6,'[1]Base de datos'!$B:$E,4,FALSE) -> 81.4
B7: =+B6+1 -> 200611005 | D7: =VLOOKUP(B7,'[1]Base de datos'!$B:$F,2,FALSE) -> Pelicula PVC 35 mic. CH 611 mm | E7: =VLOOKUP(B7,'[1]Base de datos'!$B:$E,3,FALSE) -> 2800 | F7: =VLOOKUP(B7,'[1]Base de datos'!$B:$E,4,FALSE) -> 77.2
B8: =+B7+1 -> 200611006 | D8: =VLOOKUP(B8,'[1]Base de datos'!$B:$F,2,FALSE) -> Pelicula PVC 35 mic. CH 611 mm | E8: =VLOOKUP(B8,'[1]Base de datos'!$B:$E,3,FALSE) -> 2820 | F8: =VLOOKUP(B8,'[1]Base de datos'!$B:$E,4,FALSE) -> 79.4
B9: =+B8+1 -> 200611007 | D9: =VLOOKUP(B9,'[1]Base de datos'!$B:$F,2,FALSE) -> Pelicula PVC 35 mic. CH 611 mm | E9: =VLOOKUP(B9,'[1]Base de datos'!$B:$E,3,FALSE) -> 2814 | F9: =VLOOKUP(B9,'[1]Base de datos'!$B:$E,4,FALSE) -> 78.5
B10: =+B9+1 -> 200611008 | D10: =VLOOKUP(B10,'[1]Base de datos'!$B:$F,2,FALSE) -> Pelicula PVC 35 mic. CH 611 mm | E10: =VLOOKUP(B10,'[1]Base de datos'!$B:$E,3,FALSE) -> 2913 | F10: =VLOOKUP(B10,'[1]Base de datos'!$B:$E,4,FALSE) -> 83.3
B11: =+B10+1 -> 200611009 | D11: =VLOOKUP(B11,'[1]Base de datos'!$B:$F,2,FALSE) -> Pelicula PVC 35 mic. CH 611 mm | E11: =VLOOKUP(B11,'[1]Base de datos'!$B:$E,3,FALSE) -> 2832 | F11: =VLOOKUP(B11,'[1]Base de datos'!$B:$E,4,FALSE) -> 79.7
B12: =+B11+1 -> 200611010 | D12: =VLOOKUP(B12,'[1]Base de datos'!$B:$F,2,FALSE) -> Pelicula PVC 35 mic. CH 611 mm | E12: =VLOOKUP(B12,'[1]Base de datos'!$B:$E,3,FALSE) -> 2916 | F12: =VLOOKUP(B12,'[1]Base de datos'!$B:$E,4,FALSE) -> 82.7
B13: =+B12+1 -> 200611011 | D13: =VLOOKUP(B13,'[1]Base de datos'!$B:$F,2,FALSE) -> Pelicula PVC 35 mic. CH 611 mm | E13: =VLOOKUP(B13,'[1]Base de datos'!$B:$E,3,FALSE) -> 2808 | F13: =VLOOKUP(B13,'[1]Base de datos'!$B:$E,4,FALSE) -> 80.4
B14: =+B13+1 -> 200611012 | D14: =VLOOKUP(B14,'[1]Base de datos'!$B:$F,2,FALSE) -> Pelicula PVC 35 mic. CH 611 mm | E14: =VLOOKUP(B14,'[1]Base de datos'!$B:$E,3,FALSE) -> 2827 | F14: =VLOOKUP(B14,'[1]Base de datos'!$B:$E,4,FALSE) -> 76.5
B15: =+B14+1 -> 200611013 | D15: =VLOOKUP(B15,'[1]Base de datos'!$B:$F,2,FALSE) -> Pelicula PVC 35 mic. CH 611 mm | E15: =VLOOKUP(B15,'[1]Base de datos'!$B:$E,3,FALSE) -> 2828 | F15: =VLOOKUP(B15,'[1]Base de datos'!$B:$E,4,FALSE) -> 80.1
... B152: =+B151+1 -> 200611150 | D152: =VLOOKUP(B152,'[1]Base de datos'!$B:$F,2,FALSE) -> Pelicula PVC 35 mic. CH 611 mm | E152: =VLOOKUP(B152,'[1]Base de datos'!$B:$E,3,FALSE) -> 2813 | F152: =VLOOKUP(B152,'[1]Base de datos'!$B:$E,4,FALSE) -> 80.9
B153: 200677001 | D153: =VLOOKUP(B153,'[1]Base de datos'!$B:$F,2,FALSE) -> Pelicula PVC 35 mic. CH 667 mm | E153: =VLOOKUP(B153,'[1]Base de datos'!$B:$E,3,FALSE) -> 2818 | F153: =VLOOKUP(B153,'[1]Base de datos'!$B:$E,4,FALSE) -> 89.3
B154: =+B153+1 -> 200677002 | D154: =VLOOKUP(B154,'[1]Base de datos'!$B:$F,2,FALSE) -> Pelicula PVC 35 mic. CH 667 mm | E154: =VLOOKUP(B154,'[1]Base de datos'!$B:$E,3,FALSE) -> 2818 | F154: =VLOOKUP(B154,'[1]Base de datos'!$B:$E,4,FALSE) -> 89.7
B155: =+B154+1 -> 200677003 | D155: =VLOOKUP(B155,'[1]Base de datos'!$B:$F,2,FALSE) -> Pelicula PVC 35 mic. CH 667 mm | E155: =VLOOKUP(B155,'[1]Base de datos'!$B:$E,3,FALSE) -> 2867 | F155: =VLOOKUP(B155,'[1]Base de datos'!$B:$E,4,FALSE) -> 88.7
B156: =+B155+1 -> 200677004 | D156: =VLOOKUP(B156,'[1]Base de datos'!$B:$F,2,FALSE) -> Pelicula PVC 35 mic. CH 667 mm | E156: =VLOOKUP(B156,'[1]Base de datos'!$B:$E,3,FALSE) -> 2830 | F156: =VLOOKUP(B156,'[1]Base de datos'!$B:$E,4,FALSE) -> 91.3
B157: =+B156+1 -> 200677005 | D157: =VLOOKUP(B157,'[1]Base de datos'!$B:$F,2,FALSE) -> Pelicula PVC 35 mic. CH 667 mm | E157: =VLOOKUP(B157,'[1]Base de datos'!$B:$E,3,FALSE) -> 2856 | F157: =VLOOKUP(B157,'[1]Base de datos'!$B:$E,4,FALSE) -> 91.8
B158: =+B157+1 -> 200677006 | D158: =VLOOKUP(B158,'[1]Base de datos'!$B:$F,2,FALSE) -> Pelicula PVC 35 mic. CH 667 mm | E158: =VLOOKUP(B158,'[1]Base de datos'!$B:$E,3,FALSE) -> 2897 | F158: =VLOOKUP(B158,'[1]Base de datos'!$B:$E,4,FALSE) -> 92.8
B159: =+B158+1 -> 200677007 | D159: =VLOOKUP(B159,'[1]Base de datos'!$B:$F,2,FALSE) -> Pelicula PVC 35 mic. CH 667 mm | E159: =VLOOKUP(B159,'[1]Base de datos'!$B:$E,3,FALSE) -> 2830 | F159: =VLOOKUP(B159,'[1]Base de datos'!$B:$E,4,FALSE) -> 96.1
B160: =+B159+1 -> 200677008 | D160: =VLOOKUP(B160,'[1]Base de datos'!$B:$F,2,FALSE) -> Pelicula PVC 35 mic. CH 667 mm | E160: =VLOOKUP(B160,'[1]Base de datos'!$B:$E,3,FALSE) -> 2818 | F160: =VLOOKUP(B160,'[1]Base de datos'!$B:$E,4,FALSE) -> 89.6
B161: =+B160+1 -> 200677009 | D161: =VLOOKUP(B161,'[1]Base de datos'!$B:$F,2,FALSE) -> Pelicula PVC 35 mic. CH 667 mm | E161: =VLOOKUP(B161,'[1]Base de datos'!$B:$E,3,FALSE) -> 2897 | F161: =VLOOKUP(B161,'[1]Base de datos'!$B:$E,4,FALSE) -> 92
B162: =+B161+1 -> 200677010 | D162: =VLOOKUP(B162,'[1]Base de datos'!$B:$F,2,FALSE) -> Pelicula PVC 35 mic. CH 667 mm | E162: =VLOOKUP(B162,'[1]Base de datos'!$B:$E,3,FALSE) -> 2813 | F162: =VLOOKUP(B162,'[1]Base de datos'!$B:$E,4,FALSE) -> 90.1
B163: =+B162+1 -> 200677011 | D163: =VLOOKUP(B163,'[1]Base de datos'!$B:$F,2,FALSE) -> Pelicula PVC 35 mic. CH 667 mm | E163: =VLOOKUP(B163,'[1]Base de datos'!$B:$E,3,FALSE) -> 2930 | F163: =VLOOKUP(B163,'[1]Base de datos'!$B:$E,4,FALSE) -> 93.4
B164: =+B163+1 -> 200677012 | D164: =VLOOKUP(B164,'[1]Base de datos'!$B:$F,2,FALSE) -> Pelicula PVC 35 mic. CH 667 mm | E164: =VLOOKUP(B164,'[1]Base de datos'!$B:$E,3,FALSE) -> 2833 | F164: =VLOOKUP(B164,'[1]Base de datos'!$B:$E,4,FALSE) -> 91.4
B165: =+B164+1 -> 200677013 | D165: =VLOOKUP(B165,'[1]Base de datos'!$B:$F,2,FALSE) -> Pelicula PVC 35 mic. CH 667 mm | E165: =VLOOKUP(B165,'[1]Base de datos'!$B:$E,3,FALSE) -> 2856 | F165: =VLOOKUP(B165,'[1]Base de datos'!$B:$E,4,FALSE) -> 91.9
... B228: =+B227+1 -> 200677076 | D228: =VLOOKUP(B228,'[1]Base de datos'!$B:$F,2,FALSE) -> Pelicula PVC 35 mic. CH 667 mm | E228: =VLOOKUP(B228,'[1]Base de datos'!$B:$E,3,FALSE) -> 2907 | F228: =VLOOKUP(B228,'[1]Base de datos'!$B:$E,4,FALSE) -> 92.7
B229: 200700001 | D229: =VLOOKUP(B229,'[1]Base de datos'!$B:$F,2,FALSE) -> Pet-G pelicula 45 mic. CH 667 mm | E229: =VLOOKUP(B229,'[1]Base de datos'!$B:$E,3,FALSE) -> 2271 | F229: =VLOOKUP(B229,'[1]Base de datos'!$B:$E,4,FALSE) -> 92.5
B230: =+B229+1 -> 200700002 | D230: =VLOOKUP(B230,'[1]Base de datos'!$B:$F,2,FALSE) -> Pet-G pelicula 45 mic. CH 667 mm | E230: =VLOOKUP(B230,'[1]Base de datos'!$B:$E,3,FALSE) -> 2245 | F230: =VLOOKUP(B230,'[1]Base de datos'!$B:$E,4,FALSE) -> 91
B231: =+B230+1 -> 200700003 | D231: =VLOOKUP(B231,'[1]Base de datos'!$B:$F,2,FALSE) -> Pet-G pelicula 45 mic. CH 667 mm | E231: =VLOOKUP(B231,'[1]Base de datos'!$B:$E,3,FALSE) -> 2271 | F231: =VLOOKUP(B231,'[1]Base de datos'!$B:$E,4,FALSE) -> 93.2
B232: =+B231+1 -> 200700004 | D232: =VLOOKUP(B232,'[1]Base de datos'!$B:$F,2,FALSE) -> Pet-G pelicula 45 mic. CH 667 mm | E232: =VLOOKUP(B232,'[1]Base de datos'!$B:$E,3,FALSE) -> 2176 | F232: =VLOOKUP(B232,'[1]Base de datos'!$B:$E,4,FALSE) -> 89.1
B233: =+B232+1 -> 200700005 | D233: =VLOOKUP(B233,'[1]Base de datos'!$B:$F,2,FALSE) -> Pet-G pelicula 45 mic. CH 667 mm | E233: =VLOOKUP(B233,'[1]Base de datos'!$B:$E,3,FALSE) -> 2246 | F233: =VLOOKUP(B233,'[1]Base de datos'!$B:$E,4,FALSE) -> 91.7
B234: =+B233+1 -> 200700006 | D234: =VLOOKUP(B234,'[1]Base de datos'!$B:$F,2,FALSE) -> Pet-G pelicula 45 mic. CH 667 mm | E234: =VLOOKUP(B234,'[1]Base de datos'!$B:$E,3,FALSE) -> 2246 | F234: =VLOOKUP(B234,'[1]Base de datos'!$B:$E,4,FALSE) -> 90.7
B235: =+B234+1 -> 200700007 | D235: =VLOOKUP(B235,'[1]Base de datos'!$B:$F,2,FALSE) -> Pet-G pelicula 45 mic. CH 667 mm | E235: =VLOOKUP(B235,'[1]Base de datos'!$B:$E,3,FALSE) -> 2272 | F235: =VLOOKUP(B235,'[1]Base de datos'!$B:$E,4,FALSE) -> 92.2
B236: =+B235+1 -> 200700008 | D236: =VLOOKUP(B236,'[1]Base de datos'!$B:$F,2,FALSE) -> Pet-G pelicula 45 mic. CH 667 mm | E236: =VLOOKUP(B236,'[1]Base de datos'!$B:$E,3,FALSE) -> 2248 | F236: =VLOOKUP(B236,'[1]Base de datos'!$B:$E,4,FALSE) -> 91.6
B237: =+B236+1 -> 200700009 | D237: =VLOOKUP(B237,'[1]Base de datos'!$B:$F,2,FALSE) -> Pet-G pelicula 45 mic. CH 667 mm | E237: =VLOOKUP(B237,'[1]Base de datos'!$B:$E,3,FALSE) -> 2248 | F237: =VLOOKUP(B237,'[1]Base de datos'!$B:$E,4,FALSE) -> 92.4
B238: =+B237+1 -> 200700010 | D238: =VLOOKUP(B238,'[1]Base de datos'!$B:$F,2,FALSE) -> Pet-G pelicula 45 mic. CH 667 mm | E238: =VLOOKUP(B238,'[1]Base de datos'!$B:$E,3,FALSE) -> 2230 | F238: =VLOOKUP(B238,'[1]Base de datos'!$B:$E,4,FALSE) -> 90.5
...

Sheet Inventario
A1: CODIGO DE BARRAS | B1: DESCRIPCION DEL PRODUCTO | C1: Metros | D1: Kilos | E1: TOTAL | F1: FECHA DE INVENTARIO | G1: Columna1
F2: =+NOW() -> 43615.641
A3: ='Entradas '!B:B -> 200611001 | B3: =VLOOKUP(A3,'Entradas '!B:F,3,FALSE) -> Pelicula PVC 35 mic. CH 611 mm | C3: =VLOOKUP(A3,'Entradas '!B:F,4,FALSE) -> 2820 | D3: =VLOOKUP(A3,'Entradas '!B:F,5,FALSE) -> 78 | E3: =SUMIF('Entradas '!B:B,Inventario!A3,'Entradas '!F:F)-SUMIF('Salidas '!B:B,Inventario!A3,'Salidas '!F:F) -> 0
A4: ='Entradas '!B:B -> 200611002 | B4: =VLOOKUP(A4,'Entradas '!B:F,3,FALSE) -> Pelicula PVC 35 mic. CH 611 mm | C4: =VLOOKUP(A4,'Entradas '!B:F,4,FALSE) -> 2870 | D4: =VLOOKUP(A4,'Entradas '!B:F,5,FALSE) -> 78.7 | E4: =SUMIF('Entradas '!B:B,Inventario!A4,'Entradas '!F:F)-SUMIF('Salidas '!B:B,Inventario!A4,'Salidas '!F:F) -> 0
A5: ='Entradas '!B:B -> 200611003 | B5: =VLOOKUP(A5,'Entradas '!B:F,3,FALSE) -> Pelicula PVC 35 mic. CH 611 mm | C5: =VLOOKUP(A5,'Entradas '!B:F,4,FALSE) -> 2782 | D5: =VLOOKUP(A5,'Entradas '!B:F,5,FALSE) -> 78.8 | E5: =SUMIF('Entradas '!B:B,Inventario!A5,'Entradas '!F:F)-SUMIF('Salidas '!B:B,Inventario!A5,'Salidas '!F:F) -> 0
A6: ='Entradas '!B:B -> 200611004 | B6: =VLOOKUP(A6,'Entradas '!B:F,3,FALSE) -> Pelicula PVC 35 mic. CH 611 mm | C6: =VLOOKUP(A6,'Entradas '!B:F,4,FALSE) -> 2941 | D6: =VLOOKUP(A6,'Entradas '!B:F,5,FALSE) -> 81.4 | E6: =SUMIF('Entradas '!B:B,Inventario!A6,'Entradas '!F:F)-SUMIF('Salidas '!B:B,Inventario!A6,'Salidas '!F:F) -> 0
A7: ='Entradas '!B:B -> 200611005 | B7: =VLOOKUP(A7,'Entradas '!B:F,3,FALSE) -> Pelicula PVC 35 mic. CH 611 mm | C7: =VLOOKUP(A7,'Entradas '!B:F,4,FALSE) -> 2800 | D7: =VLOOKUP(A7,'Entradas '!B:F,5,FALSE) -> 77.2 | E7: =SUMIF('Entradas '!B:B,Inventario!A7,'Entradas '!F:F)-SUMIF('Salidas '!B:B,Inventario!A7,'Salidas '!F:F) -> 0
A8: ='Entradas '!B:B -> 200611006 | B8: =VLOOKUP(A8,'Entradas '!B:F,3,FALSE) -> Pelicula PVC 35 mic. CH 611 mm | C8: =VLOOKUP(A8,'Entradas '!B:F,4,FALSE) -> 2820 | D8: =VLOOKUP(A8,'Entradas '!B:F,5,FALSE) -> 79.4 | E8: =SUMIF('Entradas '!B:B,Inventario!A8,'Entradas '!F:F)-SUMIF('Salidas '!B:B,Inventario!A8,'Salidas '!F:F) -> 79.4
A9: ='Entradas '!B:B -> 200611007 | B9: =VLOOKUP(A9,'Entradas '!B:F,3,FALSE) -> Pelicula PVC 35 mic. CH 611 mm | C9: =VLOOKUP(A9,'Entradas '!B:F,4,FALSE) -> 2814 | D9: =VLOOKUP(A9,'Entradas '!B:F,5,FALSE) -> 78.5 | E9: =SUMIF('Entradas '!B:B,Inventario!A9,'Entradas '!F:F)-SUMIF('Salidas '!B:B,Inventario!A9,'Salidas '!F:F) -> 0
A10: ='Entradas '!B:B -> 200611008 | B10: =VLOOKUP(A10,'Entradas '!B:F,3,FALSE) -> Pelicula PVC 35 mic. CH 611 mm | C10: =VLOOKUP(A10,'Entradas '!B:F,4,FALSE) -> 2913 | D10: =VLOOKUP(A10,'Entradas '!B:F,5,FALSE) -> 83.3 | E10: =SUMIF('Entradas '!B:B,Inventario!A10,'Entradas '!F:F)-SUMIF('Salidas '!B:B,Inventario!A10,'Salidas '!F:F) -> 0
A11: ='Entradas '!B:B -> 200611009 | B11: =VLOOKUP(A11,'Entradas '!B:F,3,FALSE) -> Pelicula PVC 35 mic. CH 611 mm | C11: =VLOOKUP(A11,'Entradas '!B:F,4,FALSE) -> 2832 | D11: =VLOOKUP(A11,'Entradas '!B:F,5,FALSE) -> 79.7 | E11: =SUMIF('Entradas '!B:B,Inventario!A11,'Entradas '!F:F)-SUMIF('Salidas '!B:B,Inventario!A11,'Salidas '!F:F) -> 0
A12: ='Entradas '!B:B -> 200611010 | B12: =VLOOKUP(A12,'Entradas '!B:F,3,FALSE) -> Pelicula PVC 35 mic. CH 611 mm | C12: =VLOOKUP(A12,'Entradas '!B:F,4,FALSE) -> 2916 | D12: =VLOOKUP(A12,'Entradas '!B:F,5,FALSE) -> 82.7 | E12: =SUMIF('Entradas '!B:B,Inventario!A12,'Entradas '!F:F)-SUMIF('Salidas '!B:B,Inventario!A12,'Salidas '!F:F) -> 0
A13: ='Entradas '!B:B -> 200611011 | B13: =VLOOKUP(A13,'Entradas '!B:F,3,FALSE) -> Pelicula PVC 35 mic. CH 611 mm | C13: =VLOOKUP(A13,'Entradas '!B:F,4,FALSE) -> 2808 | D13: =VLOOKUP(A13,'Entradas '!B:F,5,FALSE) -> 80.4 | E13: =SUMIF('Entradas '!B:B,Inventario!A13,'Entradas '!F:F)-SUMIF('Salidas '!B:B,Inventario!A13,'Salidas '!F:F) -> 0
A14: ='Entradas '!B:B -> 200611012 | B14: =VLOOKUP(A14,'Entradas '!B:F,3,FALSE) -> Pelicula PVC 35 mic. CH 611 mm | C14: =VLOOKUP(A14,'Entradas '!B:F,4,FALSE) -> 2827 | D14: =VLOOKUP(A14,'Entradas '!B:F,5,FALSE) -> 76.5 | E14: =SUMIF('Entradas '!B:B,Inventario!A14,'Entradas '!F:F)-SUMIF('Salidas '!B:B,Inventario!A14,'Salidas '!F:F) -> 0
... A527: ='Entradas '!B:B -> 0 | B527: =VLOOKUP(A527,'Entradas '!B:F,3,FALSE) -> #N/A | C527: =VLOOKUP(A527,'Entradas '!B:F,4,FALSE) -> #N/A | D527: =VLOOKUP(A527,'Entradas '!B:F,5,FALSE) -> #N/A | E527: =SUMIF('Entradas '!B:B,Inventario!A527,'Entradas '!F:F)-SUMIF('Salidas '!B:B,Inventario!A527,'Salidas '!F:F) -> 0
B528: =VLOOKUP(A528,'Entradas '!B:F,3,FALSE) -> #N/A | C528: =VLOOKUP(A528,'Entradas '!B:F,4,FALSE) -> #N/A | D528: =VLOOKUP(A528,'Entradas '!B:F,5,FALSE) -> #N/A | E528: =SUMIF('Entradas '!B:B,Inventario!A528,'Entradas '!F:F)-SUMIF('Salidas '!B:B,Inventario!A528,'Salidas '!F:F) -> 0

Sheet Hoja1
