Workbook

Sheet Base de datos
B1: BASE DE DATOS PRODUCTOS | E1: Total de productos | F1: =COUNT(Tabla1[Codigo de barras]) -> 406
A3: Numero | B3: Codigo de barras | C3: Nombre producto | D3: Metros | E3: Kilos | F3: Caja | G3: Codigo de barra **
A4: 1 | B4: 200611001 | C4: Pelicula PVC 35 mic. CH 611 mm | D4: 2820 | E4: 78 | F4: 1 | G4: ="*"&Tabla1[[#This Row],[Codigo de barras]]&"*" -> *200611001*
A5: =+A4+1 -> 2 | B5: =+B4+1 -> 200611002 | C5: Pelicula PVC 35 mic. CH 611 mm | D5: 2870 | E5: 78.7 | F5: 2 | G5: ="*"&Tabla1[[#This Row],[Codigo de barras]]&"*" -> *200611002*
A6: =+A5+1 -> 3 | B6: =+B5+1 -> 200611003 | C6: Pelicula PVC 35 mic. CH 611 mm | D6: 2782 | E6: 78.8 | F6: 3 | G6: ="*"&Tabla1[[#This Row],[Codigo de barras]]&"*" -> *200611003*
A7: =+A6+1 -> 4 | B7: =+B6+1 -> 200611004 | C7: Pelicula PVC 35 mic. CH 611 mm | D7: 2941 | E7: 81.4 | F7: 4 | G7: ="*"&Tabla1[[#This Row],[Codigo de barras]]&"*" -> *200611004*
A8: =+A7+1 -> 5 | B8: =+B7+1 -> 200611005 | C8: Pelicula PVC 35 mic. CH 611 mm | D8: 2800 | E8: 77.2 | F8: 5 | G8: ="*"&Tabla1[[#This Row],[Codigo de barras]]&"*" -> *200611005*
A9: =+A8+1 -> 6 | B9: =+B8+1 -> 200611006 | C9: Pelicula PVC 35 mic. CH 611 mm | D9: 2820 | E9: 79.4 | F9: 6 | G9: ="*"&Tabla1[[#This Row],[Codigo de barras]]&"*" -> *200611006*
A10: =+A9+1 -> 7 | B10: =+B9+1 -> 200611007 | C10: Pelicula PVC 35 mic. CH 611 mm | D10: 2814 | E10: 78.5 | F10: 7 | G10: ="*"&Tabla1[[#This Row],[Codigo de barras]]&"*" -> *200611007*
A11: =+A10+1 -> 8 | B11: =+B10+1 -> 200611008 | C11: Pelicula PVC 35 mic. CH 611 mm | D11: 2913 | E11: 83.3 | F11: 8 | G11: ="*"&Tabla1[[#This Row],[Codigo de barras]]&"*" -> *200611008*
A12: =+A11+1 -> 9 | B12: =+B11+1 -> 200611009 | C12: Pelicula PVC 35 mic. CH 611 mm | D12: 2832 | E12: 79.7 | F12: 9 | G12: ="*"&Tabla1[[#This Row],[Codigo de barras]]&"*" -> *200611009*
A13: =+A12+1 -> 10 | B13: =+B12+1 -> 200611010 | C13: Pelicula PVC 35 mic. CH 611 mm | D13: 2916 | E13: 82.7 | F13: 10 | G13: ="*"&Tabla1[[#This Row],[Codigo de barras]]&"*" -> *200611010*
A14: =+A13+1 -> 11 | B14: =+B13+1 -> 200611011 | C14: Pelicula PVC 35 mic. CH 611 mm | D14: 2808 | E14: 80.4 | F14: 11 | G14: ="*"&Tabla1[[#This Row],[Codigo de barras]]&"*" -> *200611011*
A15: =+A14+1 -> 12 | B15: =+B14+1 -> 200611012 | C15: Pelicula PVC 35 mic. CH 611 mm | D15: 2827 | E15: 76.5 | F15: 12 | G15: ="*"&Tabla1[[#This Row],[Codigo de barras]]&"*" -> *200611012*
A16: =+A15+1 -> 13 | B16: =+B15+1 -> 200611013 | C16: Pelicula PVC 35 mic. CH 611 mm | D16: 2828 | E16: 80.1 | F16: 13 | G16: ="*"&Tabla1[[#This Row],[Codigo de barras]]&"*" -> *200611013*
... A153: =+A152+1 -> 150 | B153: =+B152+1 -> 200611150 | C153: Pelicula PVC 35 mic. CH 611 mm | D153: 2813 | E153: 80.9 | F153: 150 | G153: ="*"&Tabla1[[#This Row],[Codigo de barras]]&"*" -> *200611150*
A154: =+A153+1 -> 151 | B154: 200677001 | C154: Pelicula PVC 35 mic. CH 667 mm | D154: 2818 | E154: 89.3 | F154: 1 | G154: ="*"&Tabla1[[#This Row],[Codigo de barras]]&"*" -> *200677001*
A155: =+A154+1 -> 152 | B155: =+B154+1 -> 200677002 | C155: Pelicula PVC 35 mic. CH 667 mm | D155: 2818 | E155: 89.7 | F155: 2 | G155: ="*"&Tabla1[[#This Row],[Codigo de barras]]&"*" -> *200677002*
A156: =+A155+1 -> 153 | B156: =+B155+1 -> 200677003 | C156: Pelicula PVC 35 mic. CH 667 mm | D156: 2867 | E156: 88.7 | F156: 3 | G156: ="*"&Tabla1[[#This Row],[Codigo de barras]]&"*" -> *200677003*
A157: =+A156+1 -> 154 | B157: =+B156+1 -> 200677004 | C157: Pelicula PVC 35 mic. CH 667 mm | D157: 2830 | E157: 91.3 | F157: 4 | G157: ="*"&Tabla1[[#This Row],[Codigo de barras]]&"*" -> *200677004*
A158: =+A157+1 -> 155 | B158: =+B157+1 -> 200677005 | C158: Pelicula PVC 35 mic. CH 667 mm | D158: 2856 | E158: 91.8 | F158: 5 | G158: ="*"&Tabla1[[#This Row],[Codigo de barras]]&"*" -> *200677005*
A159: =+A158+1 -> 156 | B159: =+B158+1 -> 200677006 | C159: Pelicula PVC 35 mic. CH 667 mm | D159: 2897 | E159: 92.8 | F159: 6 | G159: ="*"&Tabla1[[#This Row],[Codigo de barras]]&"*" -> *200677006*
A160: =+A159+1 -> 157 | B160: =+B159+1 -> 200677007 | C160: Pelicula PVC 35 mic. CH 667 mm | D160: 2830 | E160: 96.1 | F160: 7 | G160: ="*"&Tabla1[[#This Row],[Codigo de barras]]&"*" -> *200677007*
A161: =+A160+1 -> 158 | B161: =+B160+1 -> 200677008 | C161: Pelicula PVC 35 mic. CH 667 mm | D161: 2818 | E161: 89.6 | F161: 8 | G161: ="*"&Tabla1[[#This Row],[Codigo de barras]]&"*" -> *200677008*
A162: =+A161+1 -> 159 | B162: =+B161+1 -> 200677009 | C162: Pelicula PVC 35 mic. CH 667 mm | D162: 2897 | E162: 92 | F162: 9 | G162: ="*"&Tabla1[[#This Row],[Codigo de barras]]&"*" -> *200677009*
A163: =+A162+1 -> 160 | B163: =+B162+1 -> 200677010 | C163: Pelicula PVC 35 mic. CH 667 mm | D163: 2813 | E163: 90.1 | F163: 10 | G163: ="*"&Tabla1[[#This Row],[Codigo de barras]]&"*" -> *200677010*
A164: =+A163+1 -> 161 | B164: =+B163+1 -> 200677011 | C164: Pelicula PVC 35 mic. CH 667 mm | D164: 2930 | E164: 93.4 | F164: 11 | G164: ="*"&Tabla1[[#This Row],[Codigo de barras]]&"*" -> *200677011*
A165: =+A164+1 -> 162 | B165: =+B164+1 -> 200677012 | C165: Pelicula PVC 35 mic. CH 667 mm | D165: 2833 | E165: 91.4 | F165: 12 | G165: ="*"&Tabla1[[#This Row],[Codigo de barras]]&"*" -> *200677012*
A166: =+A165+1 -> 163 | B166: =+B165+1 -> 200677013 | C166: Pelicula PVC 35 mic. CH 667 mm | D166: 2856 | E166: 91.9 | F166: 13 | G166: ="*"&Tabla1[[#This Row],[Codigo de barras]]&"*" -> *200677013*
... A229: =+A228+1 -> 226 | B229: =+B228+1 -> 200677076 | C229: Pelicula PVC 35 mic. CH 667 mm | D229: 2907 | E229: 92.7 | F229: 76 | G229: ="*"&Tabla1[[#This Row],[Codigo de barras]]&"*" -> *200677076*
A230: =+A229+1 -> 227 | B230: 200700001 | C230: Pet-G pelicula 45 mic. CH 667 mm | D230: 2271 | E230: 92.5 | F230: 1 | G230: ="*"&Tabla1[[#This Row],[Codigo de barras]]&"*" -> *200700001*
A231: =+A230+1 -> 228 | B231: =+B230+1 -> 200700002 | C231: Pet-G pelicula 45 mic. CH 667 mm | D231: 2245 | E231: 91 | F231: 2 | G231: ="*"&Tabla1[[#This Row],[Codigo de barras]]&"*" -> *200700002*
A232: =+A231+1 -> 229 | B232: =+B231+1 -> 200700003 | C232: Pet-G pelicula 45 mic. CH 667 mm | D232: 2271 | E232: 93.2 | F232: 3 | G232: ="*"&Tabla1[[#This Row],[Codigo de barras]]&"*" -> *200700003*
A233: =+A232+1 -> 230 | B233: =+B232+1 -> 200700004 | C233: Pet-G pelicula 45 mic. CH 667 mm | D233: 2176 | E233: 89.1 | F233: 4 | G233: ="*"&Tabla1[[#This Row],[Codigo de barras]]&"*" -> *200700004*
A234: =+A233+1 -> 231 | B234: =+B233+1 -> 200700005 | C234: Pet-G pelicula 45 mic. CH 667 mm | D234: 2246 | E234: 91.7 | F234: 5 | G234: ="*"&Tabla1[[#This Row],[Codigo de barras]]&"*" -> *200700005*
A235: =+A234+1 -> 232 | B235: =+B234+1 -> 200700006 | C235: Pet-G pelicula 45 mic. CH 667 mm | D235: 2246 | E235: 90.7 | F235: 6 | G235: ="*"&Tabla1[[#This Row],[Codigo de barras]]&"*" -> *200700006*
A236: =+A235+1 -> 233 | B236: =+B235+1 -> 200700007 | C236: Pet-G pelicula 45 mic. CH 667 mm | D236: 2272 | E236: 92.2 | F236: 7 | G236: ="*"&Tabla1[[#This Row],[Codigo de barras]]&"*" -> *200700007*
A237: =+A236+1 -> 234 | B237: =+B236+1 -> 200700008 | C237: Pet-G pelicula 45 mic. CH 667 mm | D237: 2248 | E237: 91.6 | F237: 8 | G237: ="*"&Tabla1[[#This Row],[Codigo de barras]]&"*" -> *200700008*
A238: =+A237+1 -> 235 | B238: =+B237+1 -> 200700009 | C238: Pet-G pelicula 45 mic. CH 667 mm | D238: 2248 | E238: 92.4 | F238: 9 | G238: ="*"&Tabla1[[#This Row],[Codigo de barras]]&"*" -> *200700009*
A239: =+A238+1 -> 236 | B239: =+B238+1 -> 200700010 | C239: Pet-G pelicula 45 mic. CH 667 mm | D239: 2230 | E239: 90.5 | F239: 10 | G239: ="*"&Tabla1[[#This Row],[Codigo de barras]]&"*" -> *200700010*
...

Sheet Ingreso codigo
H1: Tamaño de. Etiqueta
B2: INGRESAR CÓDIGO DE BARRAS PARA IMPRESIÓN INGRESAR CÓDIGO DE BARRAS PARA IMPRESIÓN | H2: Alto | I2: Cantidad a la Tabla. | J2: % de desperdicio
H3: 70 | I3: 3 | J3: 0 | K3: =(100-J3)/100 -> 1
E4: Código | F4: Nombre de productos | G4: Metros | H4: Kilos | I4: Caja | J4: Piezas
B5: Código de Barras 1 | C5: 3012905201920 | E5: =IFERROR(VLOOKUP($C$5,Tabla1[],6,FALSE),"-") -> *3012905201920* | F5: =IFERROR(VLOOKUP($C$5,Tabla1[],2,FALSE),"-") -> CYAN SELECCIÓN | G5: =IFERROR(VLOOKUP($C$5,Tabla1[],3,FALSE),"-") -> 0 | H5: =IFERROR(VLOOKUP($C$5,Tabla1[],4,FALSE),"-") -> 18.5 | I5: =IFERROR(VLOOKUP($C$5,Tabla1[],5,FALSE),"-") -> 20 | J5: =+((G5*1000)/H3)*I3 -> 0
B6: Código de Barras 2 | C6: 3012905201921 | E6: =IFERROR(VLOOKUP($C$6,Tabla1[],6,FALSE),"-") -> *3012905201921* | F6: =IFERROR(VLOOKUP($C$6,Tabla1[],2,FALSE),"-") -> CYAN SELECCIÓN | G6: =IFERROR(VLOOKUP($C$6,Tabla1[],3,FALSE),"-") -> 0 | H6: =IFERROR(VLOOKUP($C$6,Tabla1[],4,FALSE),"-") -> 18.5 | I6: =IFERROR(VLOOKUP($C$6,Tabla1[],5,FALSE),"-") -> 21 | J6: =+((G6*1000)/H3)*I3 -> 0
B7: Código de Barras 3 | C7: 3012905201922 | E7: =IFERROR(VLOOKUP($C$7,Tabla1[],6,FALSE),"-") -> *3012905201922* | F7: =IFERROR(VLOOKUP($C$7,Tabla1[],2,FALSE),"-") -> CYAN SELECCIÓN | G7: =IFERROR(VLOOKUP($C$7,Tabla1[],3,FALSE),"-") -> 0 | H7: =IFERROR(VLOOKUP($C$7,Tabla1[],4,FALSE),"-") -> 18.5 | I7: =IFERROR(VLOOKUP($C$7,Tabla1[],5,FALSE),"-") -> 22 | J7: =+((G7*1000)/H3)*I3 -> 0
B8: Código de Barras 4 | C8: 3012905201923 | E8: =IFERROR(VLOOKUP($C$8,Tabla1[],6,FALSE),"-") -> *3012905201923* | F8: =IFERROR(VLOOKUP($C$8,Tabla1[],2,FALSE),"-") -> CYAN SELECCIÓN | G8: =IFERROR(VLOOKUP($C$8,Tabla1[],3,FALSE),"-") -> 0 | H8: =IFERROR(VLOOKUP($C$8,Tabla1[],4,FALSE),"-") -> 18.5 | I8: =IFERROR(VLOOKUP($C$8,Tabla1[],5,FALSE),"-") -> 23 | J8: =+((G8*1000)/H3)*I3 -> 0
B9: Código de Barras 5 | C9: 3012905201924 | E9: =IFERROR(VLOOKUP($C$9,Tabla1[],6,FALSE),"-") -> *3012905201924* | F9: =IFERROR(VLOOKUP($C$9,Tabla1[],2,FALSE),"-") -> CYAN SELECCIÓN | G9: =IFERROR(VLOOKUP($C$9,Tabla1[],3,FALSE),"-") -> 0 | H9: =IFERROR(VLOOKUP($C$9,Tabla1[],4,FALSE),"-") -> 18.5 | I9: =IFERROR(VLOOKUP($C$9,Tabla1[],5,FALSE),"-") -> 24 | J9: =+((G9*1000)/H3)*I3 -> 0
C10: 3012905201925 | E10: =IFERROR(VLOOKUP($C$10,Tabla1[],6,FALSE),"-") -> *3012905201925* | F10: =IFERROR(VLOOKUP($C$10,Tabla1[],2,FALSE),"-") -> CYAN SELECCIÓN | G10: =IFERROR(VLOOKUP($C$10,Tabla1[],3,FALSE),"-") -> 0 | H10: =IFERROR(VLOOKUP($C$10,Tabla1[],4,FALSE),"-") -> 18.5 | I10: =IFERROR(VLOOKUP($C$10,Tabla1[],5,FALSE),"-") -> 25 | J10: =+((G10*1000)/H3)*I3 -> 0
C11: 3012905201926 | E11: =IFERROR(VLOOKUP($C$11,Tabla1[],6,FALSE),"-") -> *3012905201926* | F11: =IFERROR(VLOOKUP($C$11,Tabla1[],2,FALSE),"-") -> CYAN SELECCIÓN | G11: =IFERROR(VLOOKUP($C$11,Tabla1[],3,FALSE),"-") -> 0 | H11: =IFERROR(VLOOKUP($C$11,Tabla1[],4,FALSE),"-") -> 18.5 | I11: =IFERROR(VLOOKUP($C$11,Tabla1[],5,FALSE),"-") -> 26 | J11: =+((G11*1000)/H3)*I3 -> 0
C12: 3012905201927 | E12: =IFERROR(VLOOKUP($C$12,Tabla1[],6,FALSE),"-") -> *3012905201927* | F12: =IFERROR(VLOOKUP($C$12,Tabla1[],2,FALSE),"-") -> CYAN SELECCIÓN | G12: =IFERROR(VLOOKUP($C$12,Tabla1[],3,FALSE),"-") -> 0 | H12: =IFERROR(VLOOKUP($C$12,Tabla1[],4,FALSE),"-") -> 18.5 | I12: =IFERROR(VLOOKUP($C$12,Tabla1[],5,FALSE),"-") -> 27 | J12: =+((G12*1000)/H3)*I3 -> 0
C13: 3012905201928 | E13: =IFERROR(VLOOKUP($C$13,Tabla1[],6,FALSE),"-") -> *3012905201928* | F13: =IFERROR(VLOOKUP($C$13,Tabla1[],2,FALSE),"-") -> CYAN SELECCIÓN | G13: =IFERROR(VLOOKUP($C$13,Tabla1[],3,FALSE),"-") -> 0 | H13: =IFERROR(VLOOKUP($C$13,Tabla1[],4,FALSE),"-") -> 18.5 | I13: =IFERROR(VLOOKUP($C$13,Tabla1[],5,FALSE),"-") -> 28 | J13: =+((G13*1000)/H3)*I3 -> 0
C14: 3012905201929 | E14: =IFERROR(VLOOKUP($C$14,Tabla1[],6,FALSE),"-") -> *3012905201929* | F14: =IFERROR(VLOOKUP($C$14,Tabla1[],2,FALSE),"-") -> CYAN SELECCIÓN | G14: =IFERROR(VLOOKUP($C$14,Tabla1[],3,FALSE),"-") -> 0 | H14: =IFERROR(VLOOKUP($C$14,Tabla1[],4,FALSE),"-") -> 18.5 | I14: =IFERROR(VLOOKUP($C$14,Tabla1[],5,FALSE),"-") -> 29 | J14: =+((G14*1000)/H3)*I3 -> 0
C15: 3012905201930 | E15: =IFERROR(VLOOKUP($C$15,Tabla1[],6,FALSE),"-") -> *3012905201930* | F15: =IFERROR(VLOOKUP($C$15,Tabla1[],2,FALSE),"-") -> CYAN SELECCIÓN | G15: =IFERROR(VLOOKUP($C$15,Tabla1[],3,FALSE),"-") -> 0 | H15: =IFERROR(VLOOKUP($C$15,Tabla1[],4,FALSE),"-") -> 18.5 | I15: =IFERROR(VLOOKUP($C$15,Tabla1[],5,FALSE),"-") -> 30 | J15: =+((G15*1000)/H3)*I3 -> 0
E16: =IFERROR(VLOOKUP($C$16,Tabla1[],6,FALSE),"-") -> - | F16: =IFERROR(VLOOKUP($C$16,Tabla1[],2,FALSE),"-") -> - | G16: =IFERROR(VLOOKUP($C$16,Tabla1[],3,FALSE),"-") -> - | H16: =IFERROR(VLOOKUP($C$16,Tabla1[],4,FALSE),"-") -> - | I16: =IFERROR(VLOOKUP($C$16,Tabla1[],5,FALSE),"-") -> - | J16: =+((G16*1000)/H3)*I3 -> #VALUE!
E17: =IFERROR(VLOOKUP($C$17,Tabla1[],6,FALSE),"-") -> - | F17: =IFERROR(VLOOKUP($C$17,Tabla1[],2,FALSE),"-") -> - | G17: =IFERROR(VLOOKUP($C$17,Tabla1[],3,FALSE),"-") -> - | H17: =IFERROR(VLOOKUP($C$17,Tabla1[],4,FALSE),"-") -> - | I17: =IFERROR(VLOOKUP($C$17,Tabla1[],5,FALSE),"-") -> - | J17: =+((G17*1000)/H3)*I3 -> #VALUE!
E18: =IFERROR(VLOOKUP($C$18,Tabla1[],6,FALSE),"-") -> - | F18: =IFERROR(VLOOKUP($C$18,Tabla1[],2,FALSE),"-") -> - | G18: =IFERROR(VLOOKUP($C$18,Tabla1[],3,FALSE),"-") -> - | H18: =IFERROR(VLOOKUP($C$18,Tabla1[],4,FALSE),"-") -> - | I18: =IFERROR(VLOOKUP($C$18,Tabla1[],5,FALSE),"-") -> - | J18: =+((G18*1000)/H3)*I3 -> #VALUE!
E19: =IFERROR(VLOOKUP($C$19,Tabla1[],6,FALSE),"-") -> - | F19: =IFERROR(VLOOKUP($C$19,Tabla1[],2,FALSE),"-") -> - | G19: =IFERROR(VLOOKUP($C$19,Tabla1[],3,FALSE),"-") -> - | H19: =IFERROR(VLOOKUP($C$19,Tabla1[],4,FALSE),"-") -> - | I19: =IFERROR(VLOOKUP($C$19,Tabla1[],5,FALSE),"-") -> - | J19: =+((G19*1000)/H3)*I3 -> #VALUE!
E20: =IFERROR(VLOOKUP($C$20,Tabla1[],6,FALSE),"-") -> - | F20: =IFERROR(VLOOKUP($C$20,Tabla1[],2,FALSE),"-") -> - | G20: =IFERROR(VLOOKUP($C$20,Tabla1[],3,FALSE),"-") -> - | H20: =IFERROR(VLOOKUP($C$20,Tabla1[],4,FALSE),"-") -> - | I20: =IFERROR(VLOOKUP($C$20,Tabla1[],5,FALSE),"-") -> - | J20: =+((G20*1000)/H3)*I3 -> #VALUE!
E21: =IFERROR(VLOOKUP($C$21,Tabla1[],6,FALSE),"-") -> - | F21: =IFERROR(VLOOKUP($C$21,Tabla1[],2,FALSE),"-") -> - | G21: =IFERROR(VLOOKUP($C$21,Tabla1[],3,FALSE),"-") -> - | H21: =IFERROR(VLOOKUP($C$21,Tabla1[],4,FALSE),"-") -> - | I21: =IFERROR(VLOOKUP($C$21,Tabla1[],5,FALSE),"-") -> - | J21: =+((G21*1000)/H3)*I3 -> #VALUE!
E22: =IFERROR(VLOOKUP($C$22,Tabla1[],6,FALSE),"-") -> - | F22: =IFERROR(VLOOKUP($C$22,Tabla1[],2,FALSE),"-") -> - | G22: =IFERROR(VLOOKUP($C$22,Tabla1[],3,FALSE),"-") -> - | H22: =IFERROR(VLOOKUP($C$22,Tabla1[],4,FALSE),"-") -> - | I22: =IFERROR(VLOOKUP($C$22,Tabla1[],5,FALSE),"-") -> - | J22: =+((G22*1000)/H3)*I3 -> #VALUE!
E23: =IFERROR(VLOOKUP($C$23,Tabla1[],6,FALSE),"-") -> - | F23: =IFERROR(VLOOKUP($C$23,Tabla1[],2,FALSE),"-") -> - | G23: =IFERROR(VLOOKUP($C$23,Tabla1[],3,FALSE),"-") -> - | H23: =IFERROR(VLOOKUP($C$23,Tabla1[],4,FALSE),"-") -> - | I23: =IFERROR(VLOOKUP($C$23,Tabla1[],5,FALSE),"-") -> - | J23: =+((G23*1000)/H3)*I3 -> #VALUE!
E24: =IFERROR(VLOOKUP($C$24,Tabla1[],6,FALSE),"-") -> - | F24: =IFERROR(VLOOKUP($C$24,Tabla1[],2,FALSE),"-") -> - | G24: =IFERROR(VLOOKUP($C$24,Tabla1[],3,FALSE),"-") -> - | H24: =IFERROR(VLOOKUP($C$24,Tabla1[],4,FALSE),"-") -> - | I24: =IFERROR(VLOOKUP($C$24,Tabla1[],5,FALSE),"-") -> - | J24: =+((G24*1000)/H3)*I3 -> #VALUE!
E25: =IFERROR(VLOOKUP($C$25,Tabla1[],6,FALSE),"-") -> - | F25: =IFERROR(VLOOKUP($C$25,Tabla1[],2,FALSE),"-") -> - | G25: =IFERROR(VLOOKUP($C$25,Tabla1[],3,FALSE),"-") -> - | H25: =IFERROR(VLOOKUP($C$25,Tabla1[],4,FALSE),"-") -> - | I25: =IFERROR(VLOOKUP($C$25,Tabla1[],5,FALSE),"-") -> - | J25: =+((G25*1000)/H3)*I3 -> #VALUE!
E26: =IFERROR(VLOOKUP($C$26,Tabla1[],6,FALSE),"-") -> - | F26: =IFERROR(VLOOKUP($C$26,Tabla1[],2,FALSE),"-") -> - | G26: =IFERROR(VLOOKUP($C$26,Tabla1[],3,FALSE),"-") -> - | H26: =IFERROR(VLOOKUP($C$26,Tabla1[],4,FALSE),"-") -> - | I26: =IFERROR(VLOOKUP($C$26,Tabla1[],5,FALSE),"-") -> - | J26: =+((G26*1000)/H3)*I3 -> #VALUE!
E27: =IFERROR(VLOOKUP($C$27,Tabla1[],6,FALSE),"-") -> - | F27: =IFERROR(VLOOKUP($C$27,Tabla1[],2,FALSE),"-") -> - | G27: =IFERROR(VLOOKUP($C$27,Tabla1[],3,FALSE),"-") -> - | H27: =IFERROR(VLOOKUP($C$27,Tabla1[],4,FALSE),"-") -> - | I27: =IFERROR(VLOOKUP($C$27,Tabla1[],5,FALSE),"-") -> - | J27: =+((G27*1000)/H3)*I3 -> #VALUE!
E28: =IFERROR(VLOOKUP($C$28,Tabla1[],6,FALSE),"-") -> - | F28: =IFERROR(VLOOKUP($C$28,Tabla1[],2,FALSE),"-") -> - | G28: =IFERROR(VLOOKUP($C$28,Tabla1[],3,FALSE),"-") -> - | H28: =IFERROR(VLOOKUP($C$28,Tabla1[],4,FALSE),"-") -> - | I28: =IFERROR(VLOOKUP($C$28,Tabla1[],5,FALSE),"-") -> - | J28: =+((G28*1000)/H3)*I3 -> #VALUE!
E29: =IFERROR(VLOOKUP($C$30,Tabla1[],6,FALSE),"-") -> - | F29: =IFERROR(VLOOKUP($C$29,Tabla1[],2,FALSE),"-") -> - | G29: =IFERROR(VLOOKUP($C$29,Tabla1[],3,FALSE),"-") -> - | H29: =IFERROR(VLOOKUP($C$29,Tabla1[],4,FALSE),"-") -> - | I29: =IFERROR(VLOOKUP($C$29,Tabla1[],5,FALSE),"-") -> - | J29: =+((G29*1000)/H3)*I3 -> #VALUE!
E30: =IFERROR(VLOOKUP($C$31,Tabla1[],6,FALSE),"-") -> - | F30: =IFERROR(VLOOKUP($C$30,Tabla1[],2,FALSE),"-") -> - | G30: =IFERROR(VLOOKUP($C$30,Tabla1[],3,FALSE),"-") -> - | H30: =IFERROR(VLOOKUP($C$30,Tabla1[],4,FALSE),"-") -> - | I30: =IFERROR(VLOOKUP($C$30,Tabla1[],5,FALSE),"-") -> - | J30: =+((G30*1000)/H3)*I3 -> #VALUE!

Sheet Imp. 1 item pagina
A1: ='Ingreso codigo'!$F$5 -> CYAN SELECCIÓN | C1: ='Ingreso codigo'!$F$5 -> CYAN SELECCIÓN | D1: ='Ingreso codigo'!$F$5 -> CYAN SELECCIÓN | E1: ='Ingreso codigo'!$F$5 -> CYAN SELECCIÓN | F1: ='Ingreso codigo'!$F$5 -> CYAN SELECCIÓN
A2: ='Ingreso codigo'!$E$5 -> *3012905201920* | C2: ='Ingreso codigo'!$E$5 -> *3012905201920* | D2: ='Ingreso codigo'!$E$5 -> *3012905201920* | E2: ='Ingreso codigo'!$E$5 -> *3012905201920* | F2: ='Ingreso codigo'!$E$5 -> *3012905201920*
A3: ='Ingreso codigo'!$E$5 -> *3012905201920* | C3: ='Ingreso codigo'!$E$5 -> *3012905201920* | D3: ='Ingreso codigo'!$E$5 -> *3012905201920* | E3: ='Ingreso codigo'!$E$5 -> *3012905201920* | F3: ='Ingreso codigo'!$E$5 -> *3012905201920*
A4: ='Ingreso codigo'!$G$4&" "&'Ingreso codigo'!$G$5 -> Metros 0 | B4: ='Ingreso codigo'!$I$4&" "&'Ingreso codigo'!$I$5 -> Caja 20
A5: ='Ingreso codigo'!$H$4&" "&'Ingreso codigo'!$H$5 -> Kilos 18.5 | B5: ='Ingreso codigo'!$I$4&" "&'Ingreso codigo'!$J$5 -> Caja 0 | C5: ='Ingreso codigo'!$H$4&" "&'Ingreso codigo'!$G$5 -> Kilos 0 | D5: ='Ingreso codigo'!$H$4&" "&'Ingreso codigo'!$G$5 -> Kilos 0 | E5: ='Ingreso codigo'!$H$4&" "&'Ingreso codigo'!$G$5 -> Kilos 0 | F5: ='Ingreso codigo'!$H$4&" "&'Ingreso codigo'!$G$5 -> Kilos 0
A6: ='Ingreso codigo'!$F$5 -> CYAN SELECCIÓN | C6: ='Ingreso codigo'!$F$5 -> CYAN SELECCIÓN | D6: ='Ingreso codigo'!$F$5 -> CYAN SELECCIÓN | E6: ='Ingreso codigo'!$F$5 -> CYAN SELECCIÓN | F6: ='Ingreso codigo'!$F$5 -> CYAN SELECCIÓN
A7: ='Ingreso codigo'!$E$5 -> *3012905201920* | C7: ='Ingreso codigo'!$E$5 -> *3012905201920* | D7: ='Ingreso codigo'!$E$5 -> *3012905201920* | E7: ='Ingreso codigo'!$E$5 -> *3012905201920* | F7: ='Ingreso codigo'!$E$5 -> *3012905201920*
A8: ='Ingreso codigo'!$E$5 -> *3012905201920* | C8: ='Ingreso codigo'!$E$5 -> *3012905201920* | D8: ='Ingreso codigo'!$E$5 -> *3012905201920* | E8: ='Ingreso codigo'!$E$5 -> *3012905201920* | F8: ='Ingreso codigo'!$E$5 -> *3012905201920*
A9: ='Ingreso codigo'!$H$4&" "&'Ingreso codigo'!$G$5 -> Kilos 0 | C9: ='Ingreso codigo'!$H$4&" "&'Ingreso codigo'!$G$5 -> Kilos 0 | D9: ='Ingreso codigo'!$H$4&" "&'Ingreso codigo'!$G$5 -> Kilos 0 | E9: ='Ingreso codigo'!$H$4&" "&'Ingreso codigo'!$G$5 -> Kilos 0 | F9: ='Ingreso codigo'!$H$4&" "&'Ingreso codigo'!$G$5 -> Kilos 0
A10: ='Ingreso codigo'!$F$5 -> CYAN SELECCIÓN | C10: ='Ingreso codigo'!$F$5 -> CYAN SELECCIÓN | D10: ='Ingreso codigo'!$F$5 -> CYAN SELECCIÓN | E10: ='Ingreso codigo'!$F$5 -> CYAN SELECCIÓN | F10: ='Ingreso codigo'!$F$5 -> CYAN SELECCIÓN
A11: ='Ingreso codigo'!$E$5 -> *3012905201920* | C11: ='Ingreso codigo'!$E$5 -> *3012905201920* | D11: ='Ingreso codigo'!$E$5 -> *3012905201920* | E11: ='Ingreso codigo'!$E$5 -> *3012905201920* | F11: ='Ingreso codigo'!$E$5 -> *3012905201920*
A12: ='Ingreso codigo'!$E$5 -> *3012905201920* | C12: ='Ingreso codigo'!$E$5 -> *3012905201920* | D12: ='Ingreso codigo'!$E$5 -> *3012905201920* | E12: ='Ingreso codigo'!$E$5 -> *3012905201920* | F12: ='Ingreso codigo'!$E$5 -> *3012905201920*
A13: ='Ingreso codigo'!$H$4&" "&'Ingreso codigo'!$G$5 -> Kilos 0 | C13: ='Ingreso codigo'!$H$4&" "&'Ingreso codigo'!$G$5 -> Kilos 0 | D13: ='Ingreso codigo'!$H$4&" "&'Ingreso codigo'!$G$5 -> Kilos 0 | E13: ='Ingreso codigo'!$H$4&" "&'Ingreso codigo'!$G$5 -> Kilos 0 | F13: ='Ingreso codigo'!$H$4&" "&'Ingreso codigo'!$G$5 -> Kilos 0
A14: ='Ingreso codigo'!$F$5 -> CYAN SELECCIÓN | C14: ='Ingreso codigo'!$F$5 -> CYAN SELECCIÓN | D14: ='Ingreso codigo'!$F$5 -> CYAN SELECCIÓN | E14: ='Ingreso codigo'!$F$5 -> CYAN SELECCIÓN | F14: ='Ingreso codigo'!$F$5 -> CYAN SELECCIÓN
A15: ='Ingreso codigo'!$E$5 -> *3012905201920* | C15: ='Ingreso codigo'!$E$5 -> *3012905201920* | D15: ='Ingreso codigo'!$E$5 -> *3012905201920* | E15: ='Ingreso codigo'!$E$5 -> *3012905201920* | F15: ='Ingreso codigo'!$E$5 -> *3012905201920*
A16: ='Ingreso codigo'!$E$5 -> *3012905201920* | C16: ='Ingreso codigo'!$E$5 -> *3012905201920* | D16: ='Ingreso codigo'!$E$5 -> *3012905201920* | E16: ='Ingreso codigo'!$E$5 -> *3012905201920* | F16: ='Ingreso codigo'!$E$5 -> *3012905201920*
A17: ='Ingreso codigo'!$H$4&" "&'Ingreso codigo'!$G$5 -> Kilos 0 | C17: ='Ingreso codigo'!$H$4&" "&'Ingreso codigo'!$G$5 -> Kilos 0 | D17: ='Ingreso codigo'!$H$4&" "&'Ingreso codigo'!$G$5 -> Kilos 0 | E17: ='Ingreso codigo'!$H$4&" "&'Ingreso codigo'!$G$5 -> Kilos 0 | F17: ='Ingreso codigo'!$H$4&" "&'Ingreso codigo'!$G$5 -> Kilos 0
A18: ='Ingreso codigo'!$F$5 -> CYAN SELECCIÓN | C18: ='Ingreso codigo'!$F$5 -> CYAN SELECCIÓN | D18: ='Ingreso codigo'!$F$5 -> CYAN SELECCIÓN | E18: ='Ingreso codigo'!$F$5 -> CYAN SELECCIÓN | F18: ='Ingreso codigo'!$F$5 -> CYAN SELECCIÓN
A19: ='Ingreso codigo'!$E$5 -> *3012905201920* | C19: ='Ingreso codigo'!$E$5 -> *3012905201920* | D19: ='Ingreso codigo'!$E$5 -> *3012905201920* | E19: ='Ingreso codigo'!$E$5 -> *3012905201920* | F19: ='Ingreso codigo'!$E$5 -> *3012905201920*
A20: ='Ingreso codigo'!$E$5 -> *3012905201920* | C20: ='Ingreso codigo'!$E$5 -> *3012905201920* | D20: ='Ingreso codigo'!$E$5 -> *3012905201920* | E20: ='Ingreso codigo'!$E$5 -> *3012905201920* | F20: ='Ingreso codigo'!$E$5 -> *3012905201920*
A21: ='Ingreso codigo'!$H$4&" "&'Ingreso codigo'!$G$5 -> Kilos 0 | C21: ='Ingreso codigo'!$H$4&" "&'Ingreso codigo'!$G$5 -> Kilos 0 | D21: ='Ingreso codigo'!$H$4&" "&'Ingreso codigo'!$G$5 -> Kilos 0 | E21: ='Ingreso codigo'!$H$4&" "&'Ingreso codigo'!$G$5 -> Kilos 0 | F21: ='Ingreso codigo'!$H$4&" "&'Ingreso codigo'!$G$5 -> Kilos 0
A22: ='Ingreso codigo'!$F$5 -> CYAN SELECCIÓN | C22: ='Ingreso codigo'!$F$5 -> CYAN SELECCIÓN | D22: ='Ingreso codigo'!$F$5 -> CYAN SELECCIÓN | E22: ='Ingreso codigo'!$F$5 -> CYAN SELECCIÓN | F22: ='Ingreso codigo'!$F$5 -> CYAN SELECCIÓN
A23: ='Ingreso codigo'!$E$5 -> *3012905201920* | C23: ='Ingreso codigo'!$E$5 -> *3012905201920* | D23: ='Ingreso codigo'!$E$5 -> *3012905201920* | E23: ='Ingreso codigo'!$E$5 -> *3012905201920* | F23: ='Ingreso codigo'!$E$5 -> *3012905201920*
A24: ='Ingreso codigo'!$E$5 -> *3012905201920* | C24: ='Ingreso codigo'!$E$5 -> *3012905201920* | D24: ='Ingreso codigo'!$E$5 -> *3012905201920* | E24: ='Ingreso codigo'!$E$5 -> *3012905201920* | F24: ='Ingreso codigo'!$E$5 -> *3012905201920*
A25: ='Ingreso codigo'!$H$4&" "&'Ingreso codigo'!$G$5 -> Kilos 0 | C25: ='Ingreso codigo'!$H$4&" "&'Ingreso codigo'!$G$5 -> Kilos 0 | D25: ='Ingreso codigo'!$H$4&" "&'Ingreso codigo'!$G$5 -> Kilos 0 | E25: ='Ingreso codigo'!$H$4&" "&'Ingreso codigo'!$G$5 -> Kilos 0 | F25: ='Ingreso codigo'!$H$4&" "&'Ingreso codigo'!$G$5 -> Kilos 0
A26: ='Ingreso codigo'!$F$5 -> CYAN SELECCIÓN | C26: ='Ingreso codigo'!$F$5 -> CYAN SELECCIÓN | D26: ='Ingreso codigo'!$F$5 -> CYAN SELECCIÓN | E26: ='Ingreso codigo'!$F$5 -> CYAN SELECCIÓN | F26: ='Ingreso codigo'!$F$5 -> CYAN SELECCIÓN
A27: ='Ingreso codigo'!$E$5 -> *3012905201920* | C27: ='Ingreso codigo'!$E$5 -> *3012905201920* | D27: ='Ingreso codigo'!$E$5 -> *3012905201920* | E27: ='Ingreso codigo'!$E$5 -> *3012905201920* | F27: ='Ingreso codigo'!$E$5 -> *3012905201920*
A28: ='Ingreso codigo'!$E$5 -> *3012905201920* | C28: ='Ingreso codigo'!$E$5 -> *3012905201920* | D28: ='Ingreso codigo'!$E$5 -> *3012905201920* | E28: ='Ingreso codigo'!$E$5 -> *3012905201920* | F28: ='Ingreso codigo'!$E$5 -> *3012905201920*
A29: ='Ingreso codigo'!$H$4&" "&'Ingreso codigo'!$G$5 -> Kilos 0 | C29: ='Ingreso codigo'!$H$4&" "&'Ingreso codigo'!$G$5 -> Kilos 0 | D29: ='Ingreso codigo'!$H$4&" "&'Ingreso codigo'!$G$5 -> Kilos 0 | E29: ='Ingreso codigo'!$H$4&" "&'Ingreso codigo'!$G$5 -> Kilos 0 | F29: ='Ingreso codigo'!$H$4&" "&'Ingreso codigo'!$G$5 -> Kilos 0
A30: ='Ingreso codigo'!$F$5 -> CYAN SELECCIÓN | C30: ='Ingreso codigo'!$F$5 -> CYAN SELECCIÓN | D30: ='Ingreso codigo'!$F$5 -> CYAN SELECCIÓN | E30: ='Ingreso codigo'!$F$5 -> CYAN SELECCIÓN | F30: ='Ingreso codigo'!$F$5 -> CYAN SELECCIÓN
A31: ='Ingreso codigo'!$E$5 -> *3012905201920* | C31: ='Ingreso codigo'!$E$5 -> *3012905201920* | D31: ='Ingreso codigo'!$E$5 -> *3012905201920* | E31: ='Ingreso codigo'!$E$5 -> *3012905201920* | F31: ='Ingreso codigo'!$E$5 -> *3012905201920*
A32: ='Ingreso codigo'!$E$5 -> *3012905201920* | C32: ='Ingreso codigo'!$E$5 -> *3012905201920* | D32: ='Ingreso codigo'!$E$5 -> *3012905201920* | E32: ='Ingreso codigo'!$E$5 -> *3012905201920* | F32: ='Ingreso codigo'!$E$5 -> *3012905201920*
A33: ='Ingreso codigo'!$H$4&" "&'Ingreso codigo'!$G$5 -> Kilos 0 | C33: ='Ingreso codigo'!$H$4&" "&'Ingreso codigo'!$G$5 -> Kilos 0 | D33: ='Ingreso codigo'!$H$4&" "&'Ingreso codigo'!$G$5 -> Kilos 0 | E33: ='Ingreso codigo'!$H$4&" "&'Ingreso codigo'!$G$5 -> Kilos 0 | F33: ='Ingreso codigo'!$H$4&" "&'Ingreso codigo'!$G$5 -> Kilos 0
A34: ='Ingreso codigo'!$F$5 -> CYAN SELECCIÓN | C34: ='Ingreso codigo'!$F$5 -> CYAN SELECCIÓN | D34: ='Ingreso codigo'!$F$5 -> CYAN SELECCIÓN | E34: ='Ingreso codigo'!$F$5 -> CYAN SELECCIÓN | F34: ='Ingreso codigo'!$F$5 -> CYAN SELECCIÓN
A35: ='Ingreso codigo'!$E$5 -> *3012905201920* | C35: ='Ingreso codigo'!$E$5 -> *3012905201920* | D35: ='Ingreso codigo'!$E$5 -> *3012905201920* | E35: ='Ingreso codigo'!$E$5 -> *3012905201920* | F35: ='Ingreso codigo'!$E$5 -> *3012905201920*
A36: ='Ingreso codigo'!$E$5 -> *3012905201920* | C36: ='Ingreso codigo'!$E$5 -> *3012905201920* | D36: ='Ingreso codigo'!$E$5 -> *3012905201920* | E36: ='Ingreso codigo'!$E$5 -> *3012905201920* | F36: ='Ingreso codigo'!$E$5 -> *3012905201920*
A37: ='Ingreso codigo'!$H$4&" "&'Ingreso codigo'!$G$5 -> Kilos 0 | C37: ='Ingreso codigo'!$H$4&" "&'Ingreso codigo'!$G$5 -> Kilos 0 | D37: ='Ingreso codigo'!$H$4&" "&'Ingreso codigo'!$G$5 -> Kilos 0 | E37: ='Ingreso codigo'!$H$4&" "&'Ingreso codigo'!$G$5 -> Kilos 0 | F37: ='Ingreso codigo'!$H$4&" "&'Ingreso codigo'!$G$5 -> Kilos 0
A38: ='Ingreso codigo'!$F$5 -> CYAN SELECCIÓN | C38: ='Ingreso codigo'!$F$5 -> CYAN SELECCIÓN | D38: ='Ingreso codigo'!$F$5 -> CYAN SELECCIÓN | E38: ='Ingreso codigo'!$F$5 -> CYAN SELECCIÓN | F38: ='Ingreso codigo'!$F$5 -> CYAN SELECCIÓN
A39: ='Ingreso codigo'!$E$5 -> *3012905201920* | C39: ='Ingreso codigo'!$E$5 -> *3012905201920* | D39: ='Ingreso codigo'!$E$5 -> *3012905201920* | E39: ='Ingreso codigo'!$E$5 -> *3012905201920* | F39: ='Ingreso codigo'!$E$5 -> *3012905201920*
A40: ='Ingreso codigo'!$E$5 -> *3012905201920* | C40: ='Ingreso codigo'!$E$5 -> *3012905201920* | D40: ='Ingreso codigo'!$E$5 -> *3012905201920* | E40: ='Ingreso codigo'!$E$5 -> *3012905201920* | F40: ='Ingreso codigo'!$E$5 -> *3012905201920*
...

Sheet Hoja1
A1: ='Ingreso codigo'!$F$5 -> CYAN SELECCIÓN | D1: ='Ingreso codigo'!$F$15 -> CYAN SELECCIÓN
A2: ='Ingreso codigo'!$E$5 -> *3012905201920* | D2: ='Ingreso codigo'!$E$15 -> *3012905201930*
A3: ='Ingreso codigo'!$E$5 -> *3012905201920* | D3: ='Ingreso codigo'!$E$15 -> *3012905201930*
A4: ='Ingreso codigo'!$G$4&" "&'Ingreso codigo'!$G$5 -> Metros 0 | B4: ='Ingreso codigo'!$I$4&" "&'Ingreso codigo'!$I$5 -> Caja 20 | D4: ='Ingreso codigo'!$G$4&" "&'Ingreso codigo'!$G$15 -> Metros 0 | E4: ='Ingreso codigo'!$I$4&" "&'Ingreso codigo'!$I$15 -> Caja 30
A5: ='Ingreso codigo'!$H$4&" "&'Ingreso codigo'!$H$5 -> Kilos 18.5 | B5: ='Ingreso codigo'!$J$4&" "&INT('Ingreso codigo'!$J$5) -> Piezas 0 | D5: ='Ingreso codigo'!$H$4&" "&'Ingreso codigo'!$H$15 -> Kilos 18.5 | E5: ='Ingreso codigo'!$J$4&" "&INT('Ingreso codigo'!$J$15) -> Piezas 0
A7: ='Ingreso codigo'!$F$6 -> CYAN SELECCIÓN | D7: ='Ingreso codigo'!$F$16 -> -
A8: ='Ingreso codigo'!$E$6 -> *3012905201921* | D8: ='Ingreso codigo'!$E$16 -> -
A9: ='Ingreso codigo'!$E$6 -> *3012905201921* | D9: ='Ingreso codigo'!$E$16 -> -
A10: ='Ingreso codigo'!$G$4&" "&'Ingreso codigo'!$G$6 -> Metros 0 | B10: ='Ingreso codigo'!$I$4&" "&'Ingreso codigo'!$I$6 -> Caja 21 | D10: ='Ingreso codigo'!$G$4&" "&'Ingreso codigo'!$G$16 -> Metros - | E10: ='Ingreso codigo'!$I$4&" "&'Ingreso codigo'!$I$16 -> Caja -
A11: ='Ingreso codigo'!$H$4&" "&'Ingreso codigo'!$H$6 -> Kilos 18.5 | B11: ='Ingreso codigo'!$J$4&" "&INT('Ingreso codigo'!$J$6) -> Piezas 0 | D11: ='Ingreso codigo'!$H$4&" "&'Ingreso codigo'!$H$16 -> Kilos - | E11: ='Ingreso codigo'!$J$4&" "&INT('Ingreso codigo'!$J$16) -> #VALUE!
A13: ='Ingreso codigo'!$F$7 -> CYAN SELECCIÓN | D13: ='Ingreso codigo'!$F$17 -> -
A14: ='Ingreso codigo'!$E$7 -> *3012905201922* | D14: ='Ingreso codigo'!$E$17 -> -
A15: ='Ingreso codigo'!$E$7 -> *3012905201922* | D15: ='Ingreso codigo'!$E$17 -> -
A16: ='Ingreso codigo'!$G$4&" "&'Ingreso codigo'!$G$7 -> Metros 0 | B16: ='Ingreso codigo'!$I$4&" "&'Ingreso codigo'!$I$7 -> Caja 22 | D16: ='Ingreso codigo'!$G$4&" "&'Ingreso codigo'!$G$17 -> Metros - | E16: ='Ingreso codigo'!$I$4&" "&'Ingreso codigo'!$I$17 -> Caja -
A17: ='Ingreso codigo'!$H$4&" "&'Ingreso codigo'!$H$7 -> Kilos 18.5 | B17: ='Ingreso codigo'!$J$4&" "&INT('Ingreso codigo'!$J$7) -> Piezas 0 | D17: ='Ingreso codigo'!$H$4&" "&'Ingreso codigo'!$H$17 -> Kilos - | E17: ='Ingreso codigo'!$J$4&" "&INT('Ingreso codigo'!$J$17) -> #VALUE!
A19: ='Ingreso codigo'!$F$8 -> CYAN SELECCIÓN | D19: ='Ingreso codigo'!$F$18 -> -
A20: ='Ingreso codigo'!$E$8 -> *3012905201923* | D20: ='Ingreso codigo'!$E$18 -> -
A21: ='Ingreso codigo'!$E$8 -> *3012905201923* | D21: ='Ingreso codigo'!$E$18 -> -
A22: ='Ingreso codigo'!$G$4&" "&'Ingreso codigo'!$G$8 -> Metros 0 | B22: ='Ingreso codigo'!$I$4&" "&'Ingreso codigo'!$I$8 -> Caja 23 | D22: ='Ingreso codigo'!$G$4&" "&'Ingreso codigo'!$G$18 -> Metros - | E22: ='Ingreso codigo'!$I$4&" "&'Ingreso codigo'!$I$18 -> Caja -
A23: ='Ingreso codigo'!$H$4&" "&'Ingreso codigo'!$H$8 -> Kilos 18.5 | B23: ='Ingreso codigo'!$J$4&" "&INT('Ingreso codigo'!$J$8) -> Piezas 0 | D23: ='Ingreso codigo'!$H$4&" "&'Ingreso codigo'!$H$18 -> Kilos - | E23: ='Ingreso codigo'!$J$4&" "&INT('Ingreso codigo'!$J$18) -> #VALUE!
A25: ='Ingreso codigo'!$F$9 -> CYAN SELECCIÓN | D25: ='Ingreso codigo'!$F$19 -> -
A26: ='Ingreso codigo'!$E$9 -> *3012905201924* | D26: ='Ingreso codigo'!$E$19 -> -
A27: ='Ingreso codigo'!$E$9 -> *3012905201924* | D27: ='Ingreso codigo'!$E$19 -> -
A28: ='Ingreso codigo'!$G$4&" "&'Ingreso codigo'!$G$9 -> Metros 0 | B28: ='Ingreso codigo'!$I$4&" "&'Ingreso codigo'!$I$9 -> Caja 24 | D28: ='Ingreso codigo'!$G$4&" "&'Ingreso codigo'!$G$19 -> Metros - | E28: ='Ingreso codigo'!$I$4&" "&'Ingreso codigo'!$I$19 -> Caja -
A29: ='Ingreso codigo'!$H$4&" "&'Ingreso codigo'!$H$9 -> Kilos 18.5 | B29: ='Ingreso codigo'!$J$4&" "&INT('Ingreso codigo'!$J$9) -> Piezas 0 | D29: ='Ingreso codigo'!$H$4&" "&'Ingreso codigo'!$H$19 -> Kilos - | E29: ='Ingreso codigo'!$J$4&" "&INT('Ingreso codigo'!$J$9) -> Piezas 0
A31: ='Ingreso codigo'!$F$10 -> CYAN SELECCIÓN | D31: ='Ingreso codigo'!$F$20 -> -
A32: ='Ingreso codigo'!$E$10 -> *3012905201925* | D32: ='Ingreso codigo'!$E$20 -> -
A33: ='Ingreso codigo'!$E$10 -> *3012905201925* | D33: ='Ingreso codigo'!$E$20 -> -
A34: ='Ingreso codigo'!$G$4&" "&'Ingreso codigo'!$G$10 -> Metros 0 | B34: ='Ingreso codigo'!$I$4&" "&'Ingreso codigo'!$I$10 -> Caja 25 | D34: ='Ingreso codigo'!$G$4&" "&'Ingreso codigo'!$G$20 -> Metros - | E34: ='Ingreso codigo'!$I$4&" "&'Ingreso codigo'!$I$20 -> Caja -
A35: ='Ingreso codigo'!$H$4&" "&'Ingreso codigo'!$H$10 -> Kilos 18.5 | B35: ='Ingreso codigo'!$J$4&" "&INT('Ingreso codigo'!$J$10) -> Piezas 0 | D35: ='Ingreso codigo'!$H$4&" "&'Ingreso codigo'!$H$20 -> Kilos - | E35: ='Ingreso codigo'!$J$4&" "&INT('Ingreso codigo'!$J$20) -> #VALUE!
A37: ='Ingreso codigo'!$F$11 -> CYAN SELECCIÓN | D37: ='Ingreso codigo'!$F$21 -> -
A38: ='Ingreso codigo'!$E$11 -> *3012905201926* | D38: ='Ingreso codigo'!$E$21 -> -
A39: ='Ingreso codigo'!$E$11 -> *3012905201926* | D39: ='Ingreso codigo'!$E$21 -> -
A40: ='Ingreso codigo'!$G$4&" "&'Ingreso codigo'!$G$11 -> Metros 0 | B40: ='Ingreso codigo'!$I$4&" "&'Ingreso codigo'!$I$11 -> Caja 26 | D40: ='Ingreso codigo'!$G$4&" "&'Ingreso codigo'!$G$21 -> Metros - | E40: ='Ingreso codigo'!$I$4&" "&'Ingreso codigo'!$I$21 -> Caja -
A41: ='Ingreso codigo'!$H$4&" "&'Ingreso codigo'!$H$11 -> Kilos 18.5 | B41: ='Ingreso codigo'!$J$4&" "&INT('Ingreso codigo'!$J$11) -> Piezas 0 | D41: ='Ingreso codigo'!$H$4&" "&'Ingreso codigo'!$H$21 -> Kilos - | E41: ='Ingreso codigo'!$J$4&" "&INT('Ingreso codigo'!$J$21) -> #VALUE!
A43: ='Ingreso codigo'!$F$12 -> CYAN SELECCIÓN | D43: ='Ingreso codigo'!$F$22 -> -
A44: ='Ingreso codigo'!$E$12 -> *3012905201927* | D44: ='Ingreso codigo'!$E$22 -> -
A45: ='Ingreso codigo'!$E$12 -> *3012905201927* | D45: ='Ingreso codigo'!$E$22 -> -
A46: ='Ingreso codigo'!$G$4&" "&'Ingreso codigo'!$G$12 -> Metros 0 | B46: ='Ingreso codigo'!$I$4&" "&'Ingreso codigo'!$I$12 -> Caja 27 | D46: ='Ingreso codigo'!$G$4&" "&'Ingreso codigo'!$G$22 -> Metros - | E46: ='Ingreso codigo'!$I$4&" "&'Ingreso codigo'!$I$22 -> Caja -
A47: ='Ingreso codigo'!$H$4&" "&'Ingreso codigo'!$H$12 -> Kilos 18.5 | B47: ='Ingreso codigo'!$J$4&" "&INT('Ingreso codigo'!$J$12) -> Piezas 0 | D47: ='Ingreso codigo'!$H$4&" "&'Ingreso codigo'!$H$22 -> Kilos - | E47: ='Ingreso codigo'!$J$4&" "&INT('Ingreso codigo'!$J$22) -> #VALUE!
...

Sheet imp. 3 item pagina
A1: ='Ingreso codigo'!$F$5 -> CYAN SELECCIÓN | B1: ='Ingreso codigo'!$F$5 -> CYAN SELECCIÓN | C1: ='Ingreso codigo'!$F$5 -> CYAN SELECCIÓN | D1: ='Ingreso codigo'!$F$5 -> CYAN SELECCIÓN | E1: ='Ingreso codigo'!$F$5 -> CYAN SELECCIÓN
A2: ='Ingreso codigo'!$E$5 -> *3012905201920* | B2: ='Ingreso codigo'!$E$5 -> *3012905201920* | C2: ='Ingreso codigo'!$E$5 -> *3012905201920* | D2: ='Ingreso codigo'!$E$5 -> *3012905201920* | E2: ='Ingreso codigo'!$E$5 -> *3012905201920*
A3: ='Ingreso codigo'!$E$5 -> *3012905201920* | B3: ='Ingreso codigo'!$E$5 -> *3012905201920* | C3: ='Ingreso codigo'!$E$5 -> *3012905201920* | D3: ='Ingreso codigo'!$E$5 -> *3012905201920* | E3: ='Ingreso codigo'!$E$5 -> *3012905201920*
A4: ='Ingreso codigo'!$H$4&" "&'Ingreso codigo'!$G$5 -> Kilos 0 | B4: ='Ingreso codigo'!$H$4&" "&'Ingreso codigo'!$G$5 -> Kilos 0 | C4: ='Ingreso codigo'!$H$4&" "&'Ingreso codigo'!$G$5 -> Kilos 0 | D4: ='Ingreso codigo'!$H$4&" "&'Ingreso codigo'!$G$5 -> Kilos 0 | E4: ='Ingreso codigo'!$H$4&" "&'Ingreso codigo'!$G$5 -> Kilos 0
A5: ='Ingreso codigo'!$F$5 -> CYAN SELECCIÓN | B5: ='Ingreso codigo'!$F$5 -> CYAN SELECCIÓN | C5: ='Ingreso codigo'!$F$5 -> CYAN SELECCIÓN | D5: ='Ingreso codigo'!$F$5 -> CYAN SELECCIÓN | E5: ='Ingreso codigo'!$F$5 -> CYAN SELECCIÓN
A6: ='Ingreso codigo'!$E$5 -> *3012905201920* | B6: ='Ingreso codigo'!$E$5 -> *3012905201920* | C6: ='Ingreso codigo'!$E$5 -> *3012905201920* | D6: ='Ingreso codigo'!$E$5 -> *3012905201920* | E6: ='Ingreso codigo'!$E$5 -> *3012905201920*
A7: ='Ingreso codigo'!$E$5 -> *3012905201920* | B7: ='Ingreso codigo'!$E$5 -> *3012905201920* | C7: ='Ingreso codigo'!$E$5 -> *3012905201920* | D7: ='Ingreso codigo'!$E$5 -> *3012905201920* | E7: ='Ingreso codigo'!$E$5 -> *3012905201920*
A8: ='Ingreso codigo'!$H$4&" "&'Ingreso codigo'!$G$5 -> Kilos 0 | B8: ='Ingreso codigo'!$H$4&" "&'Ingreso codigo'!$G$5 -> Kilos 0 | C8: ='Ingreso codigo'!$H$4&" "&'Ingreso codigo'!$G$5 -> Kilos 0 | D8: ='Ingreso codigo'!$H$4&" "&'Ingreso codigo'!$G$5 -> Kilos 0 | E8: ='Ingreso codigo'!$H$4&" "&'Ingreso codigo'!$G$5 -> Kilos 0
A9: ='Ingreso codigo'!$F$5 -> CYAN SELECCIÓN | B9: ='Ingreso codigo'!$F$5 -> CYAN SELECCIÓN | C9: ='Ingreso codigo'!$F$5 -> CYAN SELECCIÓN | D9: ='Ingreso codigo'!$F$5 -> CYAN SELECCIÓN | E9: ='Ingreso codigo'!$F$5 -> CYAN SELECCIÓN
A10: ='Ingreso codigo'!$E$5 -> *3012905201920* | B10: ='Ingreso codigo'!$E$5 -> *3012905201920* | C10: ='Ingreso codigo'!$E$5 -> *3012905201920* | D10: ='Ingreso codigo'!$E$5 -> *3012905201920* | E10: ='Ingreso codigo'!$E$5 -> *3012905201920*
A11: ='Ingreso codigo'!$E$5 -> *3012905201920* | B11: ='Ingreso codigo'!$E$5 -> *3012905201920* | C11: ='Ingreso codigo'!$E$5 -> *3012905201920* | D11: ='Ingreso codigo'!$E$5 -> *3012905201920* | E11: ='Ingreso codigo'!$E$5 -> *3012905201920*
A12: ='Ingreso codigo'!$H$4&" "&'Ingreso codigo'!$G$5 -> Kilos 0 | B12: ='Ingreso codigo'!$H$4&" "&'Ingreso codigo'!$G$5 -> Kilos 0 | C12: ='Ingreso codigo'!$H$4&" "&'Ingreso codigo'!$G$5 -> Kilos 0 | D12: ='Ingreso codigo'!$H$4&" "&'Ingreso codigo'!$G$5 -> Kilos 0 | E12: ='Ingreso codigo'!$H$4&" "&'Ingreso codigo'!$G$5 -> Kilos 0
A13: ='Ingreso codigo'!$F$5 -> CYAN SELECCIÓN | B13: ='Ingreso codigo'!$F$5 -> CYAN SELECCIÓN | C13: ='Ingreso codigo'!$F$5 -> CYAN SELECCIÓN | D13: ='Ingreso codigo'!$F$5 -> CYAN SELECCIÓN | E13: ='Ingreso codigo'!$F$5 -> CYAN SELECCIÓN
A14: ='Ingreso codigo'!$E$5 -> *3012905201920* | B14: ='Ingreso codigo'!$E$5 -> *3012905201920* | C14: ='Ingreso codigo'!$E$5 -> *3012905201920* | D14: ='Ingreso codigo'!$E$5 -> *3012905201920* | E14: ='Ingreso codigo'!$E$5 -> *3012905201920*
A15: ='Ingreso codigo'!$E$5 -> *3012905201920* | B15: ='Ingreso codigo'!$E$5 -> *3012905201920* | C15: ='Ingreso codigo'!$E$5 -> *3012905201920* | D15: ='Ingreso codigo'!$E$5 -> *3012905201920* | E15: ='Ingreso codigo'!$E$5 -> *3012905201920*
A16: ='Ingreso codigo'!$H$4&" "&'Ingreso codigo'!$G$5 -> Kilos 0 | B16: ='Ingreso codigo'!$H$4&" "&'Ingreso codigo'!$G$5 -> Kilos 0 | C16: ='Ingreso codigo'!$H$4&" "&'Ingreso codigo'!$G$5 -> Kilos 0 | D16: ='Ingreso codigo'!$H$4&" "&'Ingreso codigo'!$G$5 -> Kilos 0 | E16: ='Ingreso codigo'!$H$4&" "&'Ingreso codigo'!$G$5 -> Kilos 0
A18: ='Ingreso codigo'!$F$6 -> CYAN SELECCIÓN | B18: ='Ingreso codigo'!$F$6 -> CYAN SELECCIÓN | C18: ='Ingreso codigo'!$F$6 -> CYAN SELECCIÓN | D18: ='Ingreso codigo'!$F$6 -> CYAN SELECCIÓN | E18: ='Ingreso codigo'!$F$6 -> CYAN SELECCIÓN
A19: ='Ingreso codigo'!$E$6 -> *3012905201921* | B19: ='Ingreso codigo'!$E$6 -> *3012905201921* | C19: ='Ingreso codigo'!$E$6 -> *3012905201921* | D19: ='Ingreso codigo'!$E$6 -> *3012905201921* | E19: ='Ingreso codigo'!$E$6 -> *3012905201921*
A20: ='Ingreso codigo'!$E$6 -> *3012905201921* | B20: ='Ingreso codigo'!$E$6 -> *3012905201921* | C20: ='Ingreso codigo'!$E$6 -> *3012905201921* | D20: ='Ingreso codigo'!$E$6 -> *3012905201921* | E20: ='Ingreso codigo'!$E$6 -> *3012905201921*
A21: ='Ingreso codigo'!$H$4&" "&'Ingreso codigo'!$G$6 -> Kilos 0 | B21: ='Ingreso codigo'!$H$4&" "&'Ingreso codigo'!$G$6 -> Kilos 0 | C21: ='Ingreso codigo'!$H$4&" "&'Ingreso codigo'!$G$6 -> Kilos 0 | D21: ='Ingreso codigo'!$H$4&" "&'Ingreso codigo'!$G$6 -> Kilos 0 | E21: ='Ingreso codigo'!$H$4&" "&'Ingreso codigo'!$G$6 -> Kilos 0
A22: ='Ingreso codigo'!$F$6 -> CYAN SELECCIÓN | B22: ='Ingreso codigo'!$F$6 -> CYAN SELECCIÓN | C22: ='Ingreso codigo'!$F$6 -> CYAN SELECCIÓN | D22: ='Ingreso codigo'!$F$6 -> CYAN SELECCIÓN | E22: ='Ingreso codigo'!$F$6 -> CYAN SELECCIÓN
A23: ='Ingreso codigo'!$E$6 -> *3012905201921* | B23: ='Ingreso codigo'!$E$6 -> *3012905201921* | C23: ='Ingreso codigo'!$E$6 -> *3012905201921* | D23: ='Ingreso codigo'!$E$6 -> *3012905201921* | E23: ='Ingreso codigo'!$E$6 -> *3012905201921*
A24: ='Ingreso codigo'!$E$6 -> *3012905201921* | B24: ='Ingreso codigo'!$E$6 -> *3012905201921* | C24: ='Ingreso codigo'!$E$6 -> *3012905201921* | D24: ='Ingreso codigo'!$E$6 -> *3012905201921* | E24: ='Ingreso codigo'!$E$6 -> *3012905201921*
A25: ='Ingreso codigo'!$H$4&" "&'Ingreso codigo'!$G$6 -> Kilos 0 | B25: ='Ingreso codigo'!$H$4&" "&'Ingreso codigo'!$G$6 -> Kilos 0 | C25: ='Ingreso codigo'!$H$4&" "&'Ingreso codigo'!$G$6 -> Kilos 0 | D25: ='Ingreso codigo'!$H$4&" "&'Ingreso codigo'!$G$6 -> Kilos 0 | E25: ='Ingreso codigo'!$H$4&" "&'Ingreso codigo'!$G$6 -> Kilos 0
A26: ='Ingreso codigo'!$F$6 -> CYAN SELECCIÓN | B26: ='Ingreso codigo'!$F$6 -> CYAN SELECCIÓN | C26: ='Ingreso codigo'!$F$6 -> CYAN SELECCIÓN | D26: ='Ingreso codigo'!$F$6 -> CYAN SELECCIÓN | E26: ='Ingreso codigo'!$F$6 -> CYAN SELECCIÓN
A27: ='Ingreso codigo'!$E$6 -> *3012905201921* | B27: ='Ingreso codigo'!$E$6 -> *3012905201921* | C27: ='Ingreso codigo'!$E$6 -> *3012905201921* | D27: ='Ingreso codigo'!$E$6 -> *3012905201921* | E27: ='Ingreso codigo'!$E$6 -> *3012905201921*
A28: ='Ingreso codigo'!$E$6 -> *3012905201921* | B28: ='Ingreso codigo'!$E$6 -> *3012905201921* | C28: ='Ingreso codigo'!$E$6 -> *3012905201921* | D28: ='Ingreso codigo'!$E$6 -> *3012905201921* | E28: ='Ingreso codigo'!$E$6 -> *3012905201921*
A29: ='Ingreso codigo'!$H$4&" "&'Ingreso codigo'!$G$6 -> Kilos 0 | B29: ='Ingreso codigo'!$H$4&" "&'Ingreso codigo'!$G$6 -> Kilos 0 | C29: ='Ingreso codigo'!$H$4&" "&'Ingreso codigo'!$G$6 -> Kilos 0 | D29: ='Ingreso codigo'!$H$4&" "&'Ingreso codigo'!$G$6 -> Kilos 0 | E29: ='Ingreso codigo'!$H$4&" "&'Ingreso codigo'!$G$6 -> Kilos 0
A30: ='Ingreso codigo'!$F$6 -> CYAN SELECCIÓN | B30: ='Ingreso codigo'!$F$6 -> CYAN SELECCIÓN | C30: ='Ingreso codigo'!$F$6 -> CYAN SELECCIÓN | D30: ='Ingreso codigo'!$F$6 -> CYAN SELECCIÓN | E30: ='Ingreso codigo'!$F$6 -> CYAN SELECCIÓN
A31: ='Ingreso codigo'!$E$6 -> *3012905201921* | B31: ='Ingreso codigo'!$E$6 -> *3012905201921* | C31: ='Ingreso codigo'!$E$6 -> *3012905201921* | D31: ='Ingreso codigo'!$E$6 -> *3012905201921* | E31: ='Ingreso codigo'!$E$6 -> *3012905201921*
A32: ='Ingreso codigo'!$E$6 -> *3012905201921* | B32: ='Ingreso codigo'!$E$6 -> *3012905201921* | C32: ='Ingreso codigo'!$E$6 -> *3012905201921* | D32: ='Ingreso codigo'!$E$6 -> *3012905201921* | E32: ='Ingreso codigo'!$E$6 -> *3012905201921*
A33: ='Ingreso codigo'!$H$4&" "&'Ingreso codigo'!$G$6 -> Kilos 0 | B33: ='Ingreso codigo'!$H$4&" "&'Ingreso codigo'!$G$6 -> Kilos 0 | C33: ='Ingreso codigo'!$H$4&" "&'Ingreso codigo'!$G$6 -> Kilos 0 | D33: ='Ingreso codigo'!$H$4&" "&'Ingreso codigo'!$G$6 -> Kilos 0 | E33: ='Ingreso codigo'!$H$4&" "&'Ingreso codigo'!$G$6 -> Kilos 0
A35: ='Ingreso codigo'!$F$7 -> CYAN SELECCIÓN | B35: ='Ingreso codigo'!$F$7 -> CYAN SELECCIÓN | C35: ='Ingreso codigo'!$F$7 -> CYAN SELECCIÓN | D35: ='Ingreso codigo'!$F$7 -> CYAN SELECCIÓN | E35: ='Ingreso codigo'!$F$7 -> CYAN SELECCIÓN
A36: ='Ingreso codigo'!$E$7 -> *3012905201922* | B36: ='Ingreso codigo'!$E$7 -> *3012905201922* | C36: ='Ingreso codigo'!$E$7 -> *3012905201922* | D36: ='Ingreso codigo'!$E$7 -> *3012905201922* | E36: ='Ingreso codigo'!$E$7 -> *3012905201922*
A37: ='Ingreso codigo'!$E$7 -> *3012905201922* | B37: ='Ingreso codigo'!$E$7 -> *3012905201922* | C37: ='Ingreso codigo'!$E$7 -> *3012905201922* | D37: ='Ingreso codigo'!$E$7 -> *3012905201922* | E37: ='Ingreso codigo'!$E$7 -> *3012905201922*
A38: ='Ingreso codigo'!$H$4&" "&'Ingreso codigo'!$G$7 -> Kilos 0 | B38: ='Ingreso codigo'!$H$4&" "&'Ingreso codigo'!$G$7 -> Kilos 0 | C38: ='Ingreso codigo'!$H$4&" "&'Ingreso codigo'!$G$7 -> Kilos 0 | D38: ='Ingreso codigo'!$H$4&" "&'Ingreso codigo'!$G$7 -> Kilos 0 | E38: ='Ingreso codigo'!$H$4&" "&'Ingreso codigo'!$G$7 -> Kilos 0
A39: ='Ingreso codigo'!$F$7 -> CYAN SELECCIÓN | B39: ='Ingreso codigo'!$F$7 -> CYAN SELECCIÓN | C39: ='Ingreso codigo'!$F$7 -> CYAN SELECCIÓN | D39: ='Ingreso codigo'!$F$7 -> CYAN SELECCIÓN | E39: ='Ingreso codigo'!$F$7 -> CYAN SELECCIÓN
A40: ='Ingreso codigo'!$E$7 -> *3012905201922* | B40: ='Ingreso codigo'!$E$7 -> *3012905201922* | C40: ='Ingreso codigo'!$E$7 -> *3012905201922* | D40: ='Ingreso codigo'!$E$7 -> *3012905201922* | E40: ='Ingreso codigo'!$E$7 -> *3012905201922*
A41: ='Ingreso codigo'!$E$7 -> *3012905201922* | B41: ='Ingreso codigo'!$E$7 -> *3012905201922* | C41: ='Ingreso codigo'!$E$7 -> *3012905201922* | D41: ='Ingreso codigo'!$E$7 -> *3012905201922* | E41: ='Ingreso codigo'!$E$7 -> *3012905201922*
A42: ='Ingreso codigo'!$H$4&" "&'Ingreso codigo'!$G$7 -> Kilos 0 | B42: ='Ingreso codigo'!$H$4&" "&'Ingreso codigo'!$G$7 -> Kilos 0 | C42: ='Ingreso codigo'!$H$4&" "&'Ingreso codigo'!$G$7 -> Kilos 0 | D42: ='Ingreso codigo'!$H$4&" "&'Ingreso codigo'!$G$7 -> Kilos 0 | E42: ='Ingreso codigo'!$H$4&" "&'Ingreso codigo'!$G$7 -> Kilos 0
...

Sheet Imp. 5 item pagina
A1: ='Ingreso codigo'!$F$5 -> CYAN SELECCIÓN | B1: ='Ingreso codigo'!$F$6 -> CYAN SELECCIÓN | C1: ='Ingreso codigo'!$F$7 -> CYAN SELECCIÓN | D1: ='Ingreso codigo'!$F$8 -> CYAN SELECCIÓN | E1: ='Ingreso codigo'!$F$9 -> CYAN SELECCIÓN
A2: ='Ingreso codigo'!$E$5 -> *3012905201920* | B2: ='Ingreso codigo'!$E$6 -> *3012905201921* | C2: ='Ingreso codigo'!$E$7 -> *3012905201922* | D2: ='Ingreso codigo'!$E$8 -> *3012905201923* | E2: ='Ingreso codigo'!$E$9 -> *3012905201924*
A3: ='Ingreso codigo'!$E$5 -> *3012905201920* | B3: ='Ingreso codigo'!$E$6 -> *3012905201921* | C3: ='Ingreso codigo'!$E$7 -> *3012905201922* | D3: ='Ingreso codigo'!$E$8 -> *3012905201923* | E3: ='Ingreso codigo'!$E$9 -> *3012905201924*
A4: ='Ingreso codigo'!$H$4&" "&'Ingreso codigo'!$G$5 -> Kilos 0 | B4: ='Ingreso codigo'!$H$4&" "&'Ingreso codigo'!$G$6 -> Kilos 0 | C4: ='Ingreso codigo'!$H$4&" "&'Ingreso codigo'!$G$7 -> Kilos 0 | D4: ='Ingreso codigo'!$H$4&" "&'Ingreso codigo'!$G$8 -> Kilos 0 | E4: ='Ingreso codigo'!$H$4&" "&'Ingreso codigo'!$G$9 -> Kilos 0
A5: ='Ingreso codigo'!$F$5 -> CYAN SELECCIÓN | B5: ='Ingreso codigo'!$F$6 -> CYAN SELECCIÓN | C5: ='Ingreso codigo'!$F$7 -> CYAN SELECCIÓN | D5: ='Ingreso codigo'!$F$8 -> CYAN SELECCIÓN | E5: ='Ingreso codigo'!$F$9 -> CYAN SELECCIÓN
A6: ='Ingreso codigo'!$E$5 -> *3012905201920* | B6: ='Ingreso codigo'!$E$6 -> *3012905201921* | C6: ='Ingreso codigo'!$E$7 -> *3012905201922* | D6: ='Ingreso codigo'!$E$8 -> *3012905201923* | E6: ='Ingreso codigo'!$E$9 -> *3012905201924*
A7: ='Ingreso codigo'!$E$5 -> *3012905201920* | B7: ='Ingreso codigo'!$E$6 -> *3012905201921* | C7: ='Ingreso codigo'!$E$7 -> *3012905201922* | D7: ='Ingreso codigo'!$E$8 -> *3012905201923* | E7: ='Ingreso codigo'!$E$9 -> *3012905201924*
A8: ='Ingreso codigo'!$H$4&" "&'Ingreso codigo'!$G$5 -> Kilos 0 | B8: ='Ingreso codigo'!$H$4&" "&'Ingreso codigo'!$G$6 -> Kilos 0 | C8: ='Ingreso codigo'!$H$4&" "&'Ingreso codigo'!$G$7 -> Kilos 0 | D8: ='Ingreso codigo'!$H$4&" "&'Ingreso codigo'!$G$8 -> Kilos 0 | E8: ='Ingreso codigo'!$H$4&" "&'Ingreso codigo'!$G$9 -> Kilos 0
A9: ='Ingreso codigo'!$F$5 -> CYAN SELECCIÓN | B9: ='Ingreso codigo'!$F$6 -> CYAN SELECCIÓN | C9: ='Ingreso codigo'!$F$7 -> CYAN SELECCIÓN | D9: ='Ingreso codigo'!$F$8 -> CYAN SELECCIÓN | E9: ='Ingreso codigo'!$F$9 -> CYAN SELECCIÓN
A10: ='Ingreso codigo'!$E$5 -> *3012905201920* | B10: ='Ingreso codigo'!$E$6 -> *3012905201921* | C10: ='Ingreso codigo'!$E$7 -> *3012905201922* | D10: ='Ingreso codigo'!$E$8 -> *3012905201923* | E10: ='Ingreso codigo'!$E$9 -> *3012905201924*
A11: ='Ingreso codigo'!$E$5 -> *3012905201920* | B11: ='Ingreso codigo'!$E$6 -> *3012905201921* | C11: ='Ingreso codigo'!$E$7 -> *3012905201922* | D11: ='Ingreso codigo'!$E$8 -> *3012905201923* | E11: ='Ingreso codigo'!$E$9 -> *3012905201924*
A12: ='Ingreso codigo'!$H$4&" "&'Ingreso codigo'!$G$5 -> Kilos 0 | B12: ='Ingreso codigo'!$H$4&" "&'Ingreso codigo'!$G$6 -> Kilos 0 | C12: ='Ingreso codigo'!$H$4&" "&'Ingreso codigo'!$G$7 -> Kilos 0 | D12: ='Ingreso codigo'!$H$4&" "&'Ingreso codigo'!$G$8 -> Kilos 0 | E12: ='Ingreso codigo'!$H$4&" "&'Ingreso codigo'!$G$9 -> Kilos 0
A13: ='Ingreso codigo'!$F$5 -> CYAN SELECCIÓN | B13: ='Ingreso codigo'!$F$6 -> CYAN SELECCIÓN | C13: ='Ingreso codigo'!$F$7 -> CYAN SELECCIÓN | D13: ='Ingreso codigo'!$F$8 -> CYAN SELECCIÓN | E13: ='Ingreso codigo'!$F$9 -> CYAN SELECCIÓN
A14: ='Ingreso codigo'!$E$5 -> *3012905201920* | B14: ='Ingreso codigo'!$E$6 -> *3012905201921* | C14: ='Ingreso codigo'!$E$7 -> *3012905201922* | D14: ='Ingreso codigo'!$E$8 -> *3012905201923* | E14: ='Ingreso codigo'!$E$9 -> *3012905201924*
A15: ='Ingreso codigo'!$E$5 -> *3012905201920* | B15: ='Ingreso codigo'!$E$6 -> *3012905201921* | C15: ='Ingreso codigo'!$E$7 -> *3012905201922* | D15: ='Ingreso codigo'!$E$8 -> *3012905201923* | E15: ='Ingreso codigo'!$E$9 -> *3012905201924*
A16: ='Ingreso codigo'!$H$4&" "&'Ingreso codigo'!$G$5 -> Kilos 0 | B16: ='Ingreso codigo'!$H$4&" "&'Ingreso codigo'!$G$6 -> Kilos 0 | C16: ='Ingreso codigo'!$H$4&" "&'Ingreso codigo'!$G$7 -> Kilos 0 | D16: ='Ingreso codigo'!$H$4&" "&'Ingreso codigo'!$G$8 -> Kilos 0 | E16: ='Ingreso codigo'!$H$4&" "&'Ingreso codigo'!$G$9 -> Kilos 0
A17: ='Ingreso codigo'!$F$5 -> CYAN SELECCIÓN | B17: ='Ingreso codigo'!$F$6 -> CYAN SELECCIÓN | C17: ='Ingreso codigo'!$F$7 -> CYAN SELECCIÓN | D17: ='Ingreso codigo'!$F$8 -> CYAN SELECCIÓN | E17: ='Ingreso codigo'!$F$9 -> CYAN SELECCIÓN
A18: ='Ingreso codigo'!$E$5 -> *3012905201920* | B18: ='Ingreso codigo'!$E$6 -> *3012905201921* | C18: ='Ingreso codigo'!$E$7 -> *3012905201922* | D18: ='Ingreso codigo'!$E$8 -> *3012905201923* | E18: ='Ingreso codigo'!$E$9 -> *3012905201924*
A19: ='Ingreso codigo'!$E$5 -> *3012905201920* | B19: ='Ingreso codigo'!$E$6 -> *3012905201921* | C19: ='Ingreso codigo'!$E$7 -> *3012905201922* | D19: ='Ingreso codigo'!$E$8 -> *3012905201923* | E19: ='Ingreso codigo'!$E$9 -> *3012905201924*
A20: ='Ingreso codigo'!$H$4&" "&'Ingreso codigo'!$G$5 -> Kilos 0 | B20: ='Ingreso codigo'!$H$4&" "&'Ingreso codigo'!$G$6 -> Kilos 0 | C20: ='Ingreso codigo'!$H$4&" "&'Ingreso codigo'!$G$7 -> Kilos 0 | D20: ='Ingreso codigo'!$H$4&" "&'Ingreso codigo'!$G$8 -> Kilos 0 | E20: ='Ingreso codigo'!$H$4&" "&'Ingreso codigo'!$G$9 -> Kilos 0
A21: ='Ingreso codigo'!$F$5 -> CYAN SELECCIÓN | B21: ='Ingreso codigo'!$F$6 -> CYAN SELECCIÓN | C21: ='Ingreso codigo'!$F$7 -> CYAN SELECCIÓN | D21: ='Ingreso codigo'!$F$8 -> CYAN SELECCIÓN | E21: ='Ingreso codigo'!$F$9 -> CYAN SELECCIÓN
A22: ='Ingreso codigo'!$E$5 -> *3012905201920* | B22: ='Ingreso codigo'!$E$6 -> *3012905201921* | C22: ='Ingreso codigo'!$E$7 -> *3012905201922* | D22: ='Ingreso codigo'!$E$8 -> *3012905201923* | E22: ='Ingreso codigo'!$E$9 -> *3012905201924*
A23: ='Ingreso codigo'!$E$5 -> *3012905201920* | B23: ='Ingreso codigo'!$E$6 -> *3012905201921* | C23: ='Ingreso codigo'!$E$7 -> *3012905201922* | D23: ='Ingreso codigo'!$E$8 -> *3012905201923* | E23: ='Ingreso codigo'!$E$9 -> *3012905201924*
A24: ='Ingreso codigo'!$H$4&" "&'Ingreso codigo'!$G$5 -> Kilos 0 | B24: ='Ingreso codigo'!$H$4&" "&'Ingreso codigo'!$G$6 -> Kilos 0 | C24: ='Ingreso codigo'!$H$4&" "&'Ingreso codigo'!$G$7 -> Kilos 0 | D24: ='Ingreso codigo'!$H$4&" "&'Ingreso codigo'!$G$8 -> Kilos 0 | E24: ='Ingreso codigo'!$H$4&" "&'Ingreso codigo'!$G$9 -> Kilos 0
A25: ='Ingreso codigo'!$F$5 -> CYAN SELECCIÓN | B25: ='Ingreso codigo'!$F$6 -> CYAN SELECCIÓN | C25: ='Ingreso codigo'!$F$7 -> CYAN SELECCIÓN | D25: ='Ingreso codigo'!$F$8 -> CYAN SELECCIÓN | E25: ='Ingreso codigo'!$F$9 -> CYAN SELECCIÓN
A26: ='Ingreso codigo'!$E$5 -> *3012905201920* | B26: ='Ingreso codigo'!$E$6 -> *3012905201921* | C26: ='Ingreso codigo'!$E$7 -> *3012905201922* | D26: ='Ingreso codigo'!$E$8 -> *3012905201923* | E26: ='Ingreso codigo'!$E$9 -> *3012905201924*
A27: ='Ingreso codigo'!$E$5 -> *3012905201920* | B27: ='Ingreso codigo'!$E$6 -> *3012905201921* | C27: ='Ingreso codigo'!$E$7 -> *3012905201922* | D27: ='Ingreso codigo'!$E$8 -> *3012905201923* | E27: ='Ingreso codigo'!$E$9 -> *3012905201924*
A28: ='Ingreso codigo'!$H$4&" "&'Ingreso codigo'!$G$5 -> Kilos 0 | B28: ='Ingreso codigo'!$H$4&" "&'Ingreso codigo'!$G$6 -> Kilos 0 | C28: ='Ingreso codigo'!$H$4&" "&'Ingreso codigo'!$G$7 -> Kilos 0 | D28: ='Ingreso codigo'!$H$4&" "&'Ingreso codigo'!$G$8 -> Kilos 0 | E28: ='Ingreso codigo'!$H$4&" "&'Ingreso codigo'!$G$9 -> Kilos 0
A29: ='Ingreso codigo'!$F$5 -> CYAN SELECCIÓN | B29: ='Ingreso codigo'!$F$6 -> CYAN SELECCIÓN | C29: ='Ingreso codigo'!$F$7 -> CYAN SELECCIÓN | D29: ='Ingreso codigo'!$F$8 -> CYAN SELECCIÓN | E29: ='Ingreso codigo'!$F$9 -> CYAN SELECCIÓN
A30: ='Ingreso codigo'!$E$5 -> *3012905201920* | B30: ='Ingreso codigo'!$E$6 -> *3012905201921* | C30: ='Ingreso codigo'!$E$7 -> *3012905201922* | D30: ='Ingreso codigo'!$E$8 -> *3012905201923* | E30: ='Ingreso codigo'!$E$9 -> *3012905201924*
A31: ='Ingreso codigo'!$E$5 -> *3012905201920* | B31: ='Ingreso codigo'!$E$6 -> *3012905201921* | C31: ='Ingreso codigo'!$E$7 -> *3012905201922* | D31: ='Ingreso codigo'!$E$8 -> *3012905201923* | E31: ='Ingreso codigo'!$E$9 -> *3012905201924*
A32: ='Ingreso codigo'!$H$4&" "&'Ingreso codigo'!$G$5 -> Kilos 0 | B32: ='Ingreso codigo'!$H$4&" "&'Ingreso codigo'!$G$6 -> Kilos 0 | C32: ='Ingreso codigo'!$H$4&" "&'Ingreso codigo'!$G$7 -> Kilos 0 | D32: ='Ingreso codigo'!$H$4&" "&'Ingreso codigo'!$G$8 -> Kilos 0 | E32: ='Ingreso codigo'!$H$4&" "&'Ingreso codigo'!$G$9 -> Kilos 0
A33: ='Ingreso codigo'!$F$5 -> CYAN SELECCIÓN | B33: ='Ingreso codigo'!$F$6 -> CYAN SELECCIÓN | C33: ='Ingreso codigo'!$F$7 -> CYAN SELECCIÓN | D33: ='Ingreso codigo'!$F$8 -> CYAN SELECCIÓN | E33: ='Ingreso codigo'!$F$9 -> CYAN SELECCIÓN
A34: ='Ingreso codigo'!$E$5 -> *3012905201920* | B34: ='Ingreso codigo'!$E$6 -> *3012905201921* | C34: ='Ingreso codigo'!$E$7 -> *3012905201922* | D34: ='Ingreso codigo'!$E$8 -> *3012905201923* | E34: ='Ingreso codigo'!$E$9 -> *3012905201924*
A35: ='Ingreso codigo'!$E$5 -> *3012905201920* | B35: ='Ingreso codigo'!$E$6 -> *3012905201921* | C35: ='Ingreso codigo'!$E$7 -> *3012905201922* | D35: ='Ingreso codigo'!$E$8 -> *3012905201923* | E35: ='Ingreso codigo'!$E$9 -> *3012905201924*
A36: ='Ingreso codigo'!$H$4&" "&'Ingreso codigo'!$G$5 -> Kilos 0 | B36: ='Ingreso codigo'!$H$4&" "&'Ingreso codigo'!$G$6 -> Kilos 0 | C36: ='Ingreso codigo'!$H$4&" "&'Ingreso codigo'!$G$7 -> Kilos 0 | D36: ='Ingreso codigo'!$H$4&" "&'Ingreso codigo'!$G$8 -> Kilos 0 | E36: ='Ingreso codigo'!$H$4&" "&'Ingreso codigo'!$G$9 -> Kilos 0
A37: ='Ingreso codigo'!$F$5 -> CYAN SELECCIÓN | B37: ='Ingreso codigo'!$F$6 -> CYAN SELECCIÓN | C37: ='Ingreso codigo'!$F$7 -> CYAN SELECCIÓN | D37: ='Ingreso codigo'!$F$8 -> CYAN SELECCIÓN | E37: ='Ingreso codigo'!$F$9 -> CYAN SELECCIÓN
A38: ='Ingreso codigo'!$E$5 -> *3012905201920* | B38: ='Ingreso codigo'!$E$6 -> *3012905201921* | C38: ='Ingreso codigo'!$E$7 -> *3012905201922* | D38: ='Ingreso codigo'!$E$8 -> *3012905201923* | E38: ='Ingreso codigo'!$E$9 -> *3012905201924*
A39: ='Ingreso codigo'!$E$5 -> *3012905201920* | B39: ='Ingreso codigo'!$E$6 -> *3012905201921* | C39: ='Ingreso codigo'!$E$7 -> *3012905201922* | D39: ='Ingreso codigo'!$E$8 -> *3012905201923* | E39: ='Ingreso codigo'!$E$9 -> *3012905201924*
A40: ='Ingreso codigo'!$H$4&" "&'Ingreso codigo'!$G$5 -> Kilos 0 | B40: ='Ingreso codigo'!$H$4&" "&'Ingreso codigo'!$G$6 -> Kilos 0 | C40: ='Ingreso codigo'!$H$4&" "&'Ingreso codigo'!$G$7 -> Kilos 0 | D40: ='Ingreso codigo'!$H$4&" "&'Ingreso codigo'!$G$8 -> Kilos 0 | E40: ='Ingreso codigo'!$H$4&" "&'Ingreso codigo'!$G$9 -> Kilos 0
...
